from mcpi.minecraft import Minecraft
mc = Minecraft.create("mc.tokyocodingclub.com")

me = mc.getPlayerEntityId('HYPER_TOHMA')

x, y, z = mc.entity.getTilePos(me)

#y = 96
#z = 6333


def build_rayquaza(x, y, z):
    a = 133
    mc.setBlock(x+6,y+ 18,z+ 32, a)
    mc.setBlock(x+5,y+ 18,z+ 32, a)
    mc.setBlock(x+5,y+ 17,z+ 32, a)
    mc.setBlock(x+39,y+ 39,z+ 31, a)
    mc.setBlock(x+44,y+ 38,z+ 31, a)
    mc.setBlock(x+39,y+ 38,z+ 31, a)
    mc.setBlock(x+38,y+ 38,z+ 31, a)
    mc.setBlock(x+45,y+ 37,z+ 31, a)
    mc.setBlock(x+44,y+ 37,z+ 31, a)
    mc.setBlock(x+39,y+ 37,z+ 31, a)
    mc.setBlock(x+38,y+ 37,z+ 31, a)
    mc.setBlock(x+45,y+ 36,z+ 31, a)
    mc.setBlock(x+44,y+ 36,z+ 31, a)
    mc.setBlock(x+43,y+ 36,z+ 31, a)
    mc.setBlock(x+39,y+ 36,z+ 31, a)
    mc.setBlock(x+38,y+ 36,z+ 31, a)
    mc.setBlock(x+44,y+ 35,z+ 31, a)
    mc.setBlock(x+43,y+ 35,z+ 31, a)
    mc.setBlock(x+39,y+ 35,z+ 31, a)
    mc.setBlock(x+44,y+ 34,z+ 31, a)
    mc.setBlock(x+43,y+ 34,z+ 31, a)
    mc.setBlock(x+39,y+ 34,z+ 31, a)
    mc.setBlock(x+44,y+ 33,z+ 31, a)
    mc.setBlock(x+43,y+ 33,z+ 31, a)
    mc.setBlock(x+39,y+ 33,z+ 31, a)
    mc.setBlock(x+44,y+ 32,z+ 31, a)
    mc.setBlock(x+43,y+ 32,z+ 31, a)
    mc.setBlock(x+39,y+ 32,z+ 31, a)
    mc.setBlock(x+44,y+ 31,z+ 31, a)
    mc.setBlock(x+43,y+ 31,z+ 31, a)
    mc.setBlock(x+39,y+ 31,z+ 31, a)
    mc.setBlock(x+38,y+ 31,z+ 31, a)
    mc.setBlock(x+44,y+ 30,z+ 31, a)
    mc.setBlock(x+43,y+ 30,z+ 31, a)
    mc.setBlock(x+38,y+ 30,z+ 31, a)
    mc.setBlock(x+44,y+ 29,z+ 31, a)
    mc.setBlock(x+43,y+ 29,z+ 31, a)
    mc.setBlock(x+38,y+ 29,z+ 31, a)
    mc.setBlock(x+43,y+ 28,z+ 31, a)
    mc.setBlock(x+38,y+ 28,z+ 31, a)
    mc.setBlock(x+10,y+ 28,z+ 31, a)
    mc.setBlock(x+9,y+ 28,z+ 31, a)
    mc.setBlock(x+8,y+ 28,z+ 31, a)
    mc.setBlock(x+12,y+ 27,z+ 31, a)
    mc.setBlock(x+11,y+ 27,z+ 31, a)
    mc.setBlock(x+6,y+ 19,z+ 32, a)
    mc.setBlock(x+6,y+ 20,z+ 32, a)
    mc.setBlock(x+7,y+ 27,z+ 31, a)
    mc.setBlock(x+6,y+ 27,z+ 31, a)
    mc.setBlock(x+5,y+ 27,z+ 31, a)
    mc.setBlock(x+4,y+ 27,z+ 31, a)
    mc.setBlock(x+3,y+ 27,z+ 31, a)
    mc.setBlock(x+2,y+ 27,z+ 31, a)
    mc.setBlock(x+1,y+ 27,z+ 31, a)
    mc.setBlock(x+12,y+ 26,z+ 31, a)
    mc.setBlock(x+7,y+ 20,z+ 32, a)
    mc.setBlock(x+7,y+ 21,z+ 32, a)
    mc.setBlock(x+8,y+ 21,z+ 32, a)
    mc.setBlock(x+4,y+ 26,z+ 31, a)
    mc.setBlock(x+3,y+ 26,z+ 31, a)
    mc.setBlock(x+2,y+ 26,z+ 31, a)
    mc.setBlock(x+12,y+ 25,z+ 31, a)
    mc.setBlock(x+9,y+ 21,z+ 32, a)
    mc.setBlock(x+5,y+ 25,z+ 31, a)
    mc.setBlock(x+12,y+ 24,z+ 31, a)
    mc.setBlock(x+10,y+ 21,z+ 32, a)
    mc.setBlock(x+5,y+ 24,z+ 31, a)
    mc.setBlock(x+12,y+ 23,z+ 31, a)
    mc.setBlock(x+6,y+ 22,z+ 32, a)
    mc.setBlock(x+11,y+ 22,z+ 32, a)
    mc.setBlock(x+5,y+ 23,z+ 31, a)
    mc.setBlock(x+11,y+ 22,z+ 31, a)
    mc.setBlock(x+5,y+ 23,z+ 32, a)
    mc.setBlock(x+12,y+ 23,z+ 32, a)
    mc.setBlock(x+5,y+ 24,z+ 32, a)
    mc.setBlock(x+5,y+ 22,z+ 31, a)
    mc.setBlock(x+10,y+ 21,z+ 31, a)
    mc.setBlock(x+9,y+ 21,z+ 31, a)
    mc.setBlock(x+8,y+ 21,z+ 31, a)
    mc.setBlock(x+12,y+ 24,z+ 32, a)
    mc.setBlock(x+6,y+ 21,z+ 31, a)
    mc.setBlock(x+7,y+ 20,z+ 31, a)
    mc.setBlock(x+6,y+ 20,z+ 31, a)
    mc.setBlock(x+6,y+ 19,z+ 31, a)
    mc.setBlock(x+5,y+ 19,z+ 31, a)
    mc.setBlock(x+6,y+ 18,z+ 31, a)
    mc.setBlock(x+5,y+ 18,z+ 31, a)
    mc.setBlock(x+5,y+ 17,z+ 31, a)
    mc.setBlock(x+39,y+ 39,z+ 30, a)
    mc.setBlock(x+44,y+ 38,z+ 30, a)
    mc.setBlock(x+43,y+ 38,z+ 30, a)
    mc.setBlock(x+39,y+ 38,z+ 30, a)
    mc.setBlock(x+38,y+ 38,z+ 30, a)
    mc.setBlock(x+44,y+ 37,z+ 30, a)
    mc.setBlock(x+43,y+ 37,z+ 30, a)
    mc.setBlock(x+39,y+ 37,z+ 30, a)
    mc.setBlock(x+43,y+ 36,z+ 30, a)
    mc.setBlock(x+42,y+ 36,z+ 30, a)
    mc.setBlock(x+41,y+ 36,z+ 30, a)
    mc.setBlock(x+40,y+ 36,z+ 30, a)
    mc.setBlock(x+39,y+ 36,z+ 30, a)
    mc.setBlock(x+43,y+ 35,z+ 30, a)
    mc.setBlock(x+42,y+ 35,z+ 30, a)
    mc.setBlock(x+41,y+ 35,z+ 30, a)
    mc.setBlock(x+40,y+ 35,z+ 30, a)
    mc.setBlock(x+5,y+ 25,z+ 32, a)
    mc.setBlock(x+38,y+ 35,z+ 30, a)
    mc.setBlock(x+43,y+ 34,z+ 30, a)
    mc.setBlock(x+42,y+ 34,z+ 30, a)
    mc.setBlock(x+41,y+ 34,z+ 30, a)
    mc.setBlock(x+40,y+ 34,z+ 30, a)
    mc.setBlock(x+13,y+ 25,z+ 32, a)
    mc.setBlock(x+38,y+ 34,z+ 30, a)
    mc.setBlock(x+43,y+ 33,z+ 30, a)
    mc.setBlock(x+42,y+ 33,z+ 30, a)
    mc.setBlock(x+41,y+ 33,z+ 30, a)
    mc.setBlock(x+40,y+ 33,z+ 30, a)
    mc.setBlock(x+4,y+ 26,z+ 32, a)
    mc.setBlock(x+38,y+ 33,z+ 30, a)
    mc.setBlock(x+43,y+ 32,z+ 30, a)
    mc.setBlock(x+42,y+ 32,z+ 30, a)
    mc.setBlock(x+41,y+ 32,z+ 30, a)
    mc.setBlock(x+40,y+ 32,z+ 30, a)
    mc.setBlock(x+5,y+ 26,z+ 32, a)
    mc.setBlock(x+38,y+ 32,z+ 30, a)
    mc.setBlock(x+43,y+ 31,z+ 30, a)
    mc.setBlock(x+42,y+ 31,z+ 30, a)
    mc.setBlock(x+41,y+ 31,z+ 30, a)
    mc.setBlock(x+40,y+ 31,z+ 30, a)
    mc.setBlock(x+13,y+ 26,z+ 32, a)
    mc.setBlock(x+38,y+ 31,z+ 30, a)
    mc.setBlock(x+43,y+ 30,z+ 30, a)
    mc.setBlock(x+42,y+ 30,z+ 30, a)
    mc.setBlock(x+41,y+ 30,z+ 30, a)
    mc.setBlock(x+40,y+ 30,z+ 30, a)
    mc.setBlock(x+39,y+ 30,z+ 30, a)
    mc.setBlock(x+38,y+ 30,z+ 30, a)
    mc.setBlock(x+43,y+ 29,z+ 30, a)
    mc.setBlock(x+42,y+ 29,z+ 30, a)
    mc.setBlock(x+41,y+ 29,z+ 30, a)
    mc.setBlock(x+40,y+ 29,z+ 30, a)
    mc.setBlock(x+39,y+ 29,z+ 30, a)
    mc.setBlock(x+38,y+ 29,z+ 30, a)
    mc.setBlock(x+43,y+ 28,z+ 30, a)
    mc.setBlock(x+42,y+ 28,z+ 30, a)
    mc.setBlock(x+39,y+ 28,z+ 30, a)
    mc.setBlock(x+38,y+ 28,z+ 30, a)
    mc.setBlock(x+10,y+ 28,z+ 30, a)
    mc.setBlock(x+9,y+ 28,z+ 30, a)
    mc.setBlock(x+8,y+ 28,z+ 30, a)
    mc.setBlock(x+11,y+ 27,z+ 30, a)
    mc.setBlock(x+4,y+ 27,z+ 32, a)
    mc.setBlock(x+5,y+ 27,z+ 32, a)
    mc.setBlock(x+6,y+ 27,z+ 32, a)
    mc.setBlock(x+7,y+ 27,z+ 30, a)
    mc.setBlock(x+6,y+ 27,z+ 30, a)
    mc.setBlock(x+3,y+ 27,z+ 30, a)
    mc.setBlock(x+2,y+ 27,z+ 30, a)
    mc.setBlock(x+1,y+ 27,z+ 30, a)
    mc.setBlock(x+12,y+ 26,z+ 30, a)
    mc.setBlock(x+7,y+ 27,z+ 32, a)
    mc.setBlock(x+13,y+ 27,z+ 32, a)
    mc.setBlock(x+5,y+ 26,z+ 30, a)
    mc.setBlock(x+4,y+ 26,z+ 30, a)
    mc.setBlock(x+3,y+ 26,z+ 30, a)
    mc.setBlock(x+2,y+ 26,z+ 30, a)
    mc.setBlock(x+1,y+ 26,z+ 30, a)
    mc.setBlock(x+12,y+ 25,z+ 30, a)
    mc.setBlock(x+8,y+ 28,z+ 32, a)
    mc.setBlock(x+9,y+ 28,z+ 32, a)
    mc.setBlock(x+4,y+ 25,z+ 30, a)
    mc.setBlock(x+12,y+ 24,z+ 30, a)
    mc.setBlock(x+10,y+ 28,z+ 32, a)
    mc.setBlock(x+5,y+ 24,z+ 30, a)
    mc.setBlock(x+12,y+ 23,z+ 30, a)
    mc.setBlock(x+11,y+ 28,z+ 32, a)
    mc.setBlock(x+5,y+ 23,z+ 30, a)
    mc.setBlock(x+14,y+ 22,z+ 30, a)
    mc.setBlock(x+13,y+ 22,z+ 30, a)
    mc.setBlock(x+12,y+ 22,z+ 30, a)
    mc.setBlock(x+11,y+ 22,z+ 30, a)
    mc.setBlock(x+12,y+ 28,z+ 32, a)
    mc.setBlock(x+38,y+ 29,z+ 32, a)
    mc.setBlock(x+5,y+ 22,z+ 30, a)
    mc.setBlock(x+14,y+ 21,z+ 30, a)
    mc.setBlock(x+10,y+ 21,z+ 30, a)
    mc.setBlock(x+9,y+ 21,z+ 30, a)
    mc.setBlock(x+43,y+ 29,z+ 32, a)
    mc.setBlock(x+44,y+ 29,z+ 32, a)
    mc.setBlock(x+45,y+ 29,z+ 32, a)
    mc.setBlock(x+5,y+ 21,z+ 30, a)
    mc.setBlock(x+8,y+ 20,z+ 30, a)
    mc.setBlock(x+7,y+ 20,z+ 30, a)
    mc.setBlock(x+6,y+ 20,z+ 30, a)
    mc.setBlock(x+6,y+ 19,z+ 30, a)
    mc.setBlock(x+5,y+ 19,z+ 30, a)
    mc.setBlock(x+6,y+ 18,z+ 30, a)
    mc.setBlock(x+5,y+ 18,z+ 30, a)
    mc.setBlock(x+5,y+ 17,z+ 30, a)
    mc.setBlock(x+5,y+ 16,z+ 30, a)
    mc.setBlock(x+42,y+ 39,z+ 29, a)
    mc.setBlock(x+40,y+ 39,z+ 29, a)
    mc.setBlock(x+39,y+ 39,z+ 29, a)
    mc.setBlock(x+43,y+ 38,z+ 29, a)
    mc.setBlock(x+42,y+ 38,z+ 29, a)
    mc.setBlock(x+41,y+ 38,z+ 29, a)
    mc.setBlock(x+40,y+ 38,z+ 29, a)
    mc.setBlock(x+38,y+ 30,z+ 32, a)
    mc.setBlock(x+38,y+ 38,z+ 29, a)
    mc.setBlock(x+43,y+ 37,z+ 29, a)
    mc.setBlock(x+42,y+ 37,z+ 29, a)
    mc.setBlock(x+41,y+ 37,z+ 29, a)
    mc.setBlock(x+40,y+ 37,z+ 29, a)
    mc.setBlock(x+44,y+ 30,z+ 32, a)
    mc.setBlock(x+38,y+ 37,z+ 29, a)
    mc.setBlock(x+43,y+ 36,z+ 29, a)
    mc.setBlock(x+45,y+ 30,z+ 32, a)
    mc.setBlock(x+38,y+ 31,z+ 32, a)
    mc.setBlock(x+39,y+ 31,z+ 32, a)
    mc.setBlock(x+44,y+ 31,z+ 32, a)
    mc.setBlock(x+38,y+ 36,z+ 29, a)
    mc.setBlock(x+43,y+ 35,z+ 29, a)
    mc.setBlock(x+45,y+ 31,z+ 32, a)
    mc.setBlock(x+38,y+ 32,z+ 32, a)
    mc.setBlock(x+39,y+ 32,z+ 32, a)
    mc.setBlock(x+37,y+ 35,z+ 29, a)
    mc.setBlock(x+36,y+ 35,z+ 29, a)
    mc.setBlock(x+43,y+ 34,z+ 29, a)
    mc.setBlock(x+44,y+ 32,z+ 32, a)
    mc.setBlock(x+45,y+ 32,z+ 32, a)
    mc.setBlock(x+37,y+ 34,z+ 29, a)
    mc.setBlock(x+43,y+ 33,z+ 29, a)
    mc.setBlock(x+38,y+ 33,z+ 32, a)
    mc.setBlock(x+39,y+ 33,z+ 32, a)
    mc.setBlock(x+37,y+ 33,z+ 29, a)
    mc.setBlock(x+43,y+ 32,z+ 29, a)
    mc.setBlock(x+44,y+ 33,z+ 32, a)
    mc.setBlock(x+45,y+ 33,z+ 32, a)
    mc.setBlock(x+37,y+ 32,z+ 29, a)
    mc.setBlock(x+42,y+ 31,z+ 29, a)
    mc.setBlock(x+37,y+ 31,z+ 29, a)
    mc.setBlock(x+42,y+ 30,z+ 29, a)
    mc.setBlock(x+38,y+ 34,z+ 32, a)
    mc.setBlock(x+39,y+ 34,z+ 32, a)
    mc.setBlock(x+37,y+ 30,z+ 29, a)
    mc.setBlock(x+42,y+ 29,z+ 29, a)
    mc.setBlock(x+44,y+ 34,z+ 32, a)
    mc.setBlock(x+45,y+ 34,z+ 32, a)
    mc.setBlock(x+38,y+ 35,z+ 32, a)
    mc.setBlock(x+37,y+ 29,z+ 29, a)
    mc.setBlock(x+10,y+ 29,z+ 29, a)
    mc.setBlock(x+42,y+ 28,z+ 29, a)
    mc.setBlock(x+41,y+ 28,z+ 29, a)
    mc.setBlock(x+40,y+ 28,z+ 29, a)
    mc.setBlock(x+39,y+ 35,z+ 32, a)
    mc.setBlock(x+44,y+ 35,z+ 32, a)
    mc.setBlock(x+37,y+ 28,z+ 29, a)
    mc.setBlock(x+10,y+ 28,z+ 29, a)
    mc.setBlock(x+41,y+ 27,z+ 29, a)
    mc.setBlock(x+40,y+ 27,z+ 29, a)
    mc.setBlock(x+39,y+ 27,z+ 29, a)
    mc.setBlock(x+38,y+ 27,z+ 29, a)
    mc.setBlock(x+37,y+ 27,z+ 29, a)
    mc.setBlock(x+11,y+ 27,z+ 29, a)
    mc.setBlock(x+45,y+ 35,z+ 32, a)
    mc.setBlock(x+9,y+ 27,z+ 29, a)
    mc.setBlock(x+8,y+ 27,z+ 29, a)
    mc.setBlock(x+7,y+ 27,z+ 29, a)
    mc.setBlock(x+6,y+ 27,z+ 29, a)
    mc.setBlock(x+1,y+ 27,z+ 29, a)
    mc.setBlock(x+40,y+ 26,z+ 29, a)
    mc.setBlock(x+39,y+ 26,z+ 29, a)
    mc.setBlock(x+38,y+ 26,z+ 29, a)
    mc.setBlock(x+37,y+ 26,z+ 29, a)
    mc.setBlock(x+11,y+ 26,z+ 29, a)
    mc.setBlock(x+38,y+ 36,z+ 32, a)
    mc.setBlock(x+39,y+ 36,z+ 32, a)
    mc.setBlock(x+5,y+ 26,z+ 29, a)
    mc.setBlock(x+4,y+ 26,z+ 29, a)
    mc.setBlock(x+3,y+ 26,z+ 29, a)
    mc.setBlock(x+2,y+ 26,z+ 29, a)
    mc.setBlock(x+1,y+ 26,z+ 29, a)
    mc.setBlock(x+11,y+ 25,z+ 29, a)
    mc.setBlock(x+44,y+ 36,z+ 32, a)
    mc.setBlock(x+45,y+ 36,z+ 32, a)
    mc.setBlock(x+3,y+ 25,z+ 29, a)
    mc.setBlock(x+2,y+ 25,z+ 29, a)
    mc.setBlock(x+11,y+ 24,z+ 29, a)
    mc.setBlock(x+38,y+ 37,z+ 32, a)
    mc.setBlock(x+4,y+ 24,z+ 29, a)
    mc.setBlock(x+11,y+ 23,z+ 29, a)
    mc.setBlock(x+39,y+ 37,z+ 32, a)
    mc.setBlock(x+4,y+ 23,z+ 29, a)
    mc.setBlock(x+14,y+ 22,z+ 29, a)
    mc.setBlock(x+13,y+ 22,z+ 29, a)
    mc.setBlock(x+12,y+ 22,z+ 29, a)
    mc.setBlock(x+11,y+ 22,z+ 29, a)
    mc.setBlock(x+44,y+ 37,z+ 32, a)
    mc.setBlock(x+45,y+ 37,z+ 32, a)
    mc.setBlock(x+4,y+ 22,z+ 29, a)
    mc.setBlock(x+14,y+ 21,z+ 29, a)
    mc.setBlock(x+13,y+ 21,z+ 29, a)
    mc.setBlock(x+12,y+ 21,z+ 29, a)
    mc.setBlock(x+10,y+ 21,z+ 29, a)
    mc.setBlock(x+38,y+ 38,z+ 32, a)
    mc.setBlock(x+39,y+ 38,z+ 32, a)
    mc.setBlock(x+5,y+ 21,z+ 29, a)
    mc.setBlock(x+9,y+ 20,z+ 29, a)
    mc.setBlock(x+8,y+ 20,z+ 29, a)
    mc.setBlock(x+7,y+ 20,z+ 29, a)
    mc.setBlock(x+5,y+ 18,z+ 33, a)
    mc.setBlock(x+5,y+ 20,z+ 29, a)
    mc.setBlock(x+6,y+ 19,z+ 29, a)
    mc.setBlock(x+5,y+ 19,z+ 29, a)
    mc.setBlock(x+5,y+ 18,z+ 29, a)
    mc.setBlock(x+5,y+ 17,z+ 29, a)
    mc.setBlock(x+4,y+ 17,z+ 29, a)
    mc.setBlock(x+5,y+ 16,z+ 29, a)
    mc.setBlock(x+4,y+ 16,z+ 29, a)
    mc.setBlock(x+42,y+ 40,z+ 28, a)
    mc.setBlock(x+41,y+ 40,z+ 28, a)
    mc.setBlock(x+40,y+ 40,z+ 28, a)
    mc.setBlock(x+39,y+ 40,z+ 28, a)
    mc.setBlock(x+38,y+ 40,z+ 28, a)
    mc.setBlock(x+42,y+ 39,z+ 28, a)
    mc.setBlock(x+41,y+ 39,z+ 28, a)
    mc.setBlock(x+6,y+ 18,z+ 33, a)
    mc.setBlock(x+6,y+ 19,z+ 33, a)
    mc.setBlock(x+38,y+ 39,z+ 28, a)
    mc.setBlock(x+37,y+ 39,z+ 28, a)
    mc.setBlock(x+42,y+ 38,z+ 28, a)
    mc.setBlock(x+6,y+ 20,z+ 33, a)
    mc.setBlock(x+7,y+ 20,z+ 33, a)
    mc.setBlock(x+37,y+ 38,z+ 28, a)
    mc.setBlock(x+43,y+ 37,z+ 28, a)
    mc.setBlock(x+7,y+ 21,z+ 33, a)
    mc.setBlock(x+7,y+ 22,z+ 33, a)
    mc.setBlock(x+37,y+ 37,z+ 28, a)
    mc.setBlock(x+36,y+ 37,z+ 28, a)
    mc.setBlock(x+43,y+ 36,z+ 28, a)
    mc.setBlock(x+8,y+ 22,z+ 33, a)
    mc.setBlock(x+9,y+ 22,z+ 33, a)
    mc.setBlock(x+37,y+ 36,z+ 28, a)
    mc.setBlock(x+36,y+ 36,z+ 28, a)
    mc.setBlock(x+35,y+ 36,z+ 28, a)
    mc.setBlock(x+43,y+ 35,z+ 28, a)
    mc.setBlock(x+10,y+ 22,z+ 33, a)
    mc.setBlock(x+6,y+ 23,z+ 33, a)
    mc.setBlock(x+11,y+ 23,z+ 33, a)
    mc.setBlock(x+12,y+ 23,z+ 33, a)
    mc.setBlock(x+35,y+ 35,z+ 28, a)
    mc.setBlock(x+43,y+ 34,z+ 28, a)
    mc.setBlock(x+6,y+ 24,z+ 33, a)
    mc.setBlock(x+13,y+ 24,z+ 33, a)
    mc.setBlock(x+36,y+ 34,z+ 28, a)
    mc.setBlock(x+35,y+ 34,z+ 28, a)
    mc.setBlock(x+34,y+ 34,z+ 28, a)
    mc.setBlock(x+43,y+ 33,z+ 28, a)
    mc.setBlock(x+6,y+ 25,z+ 33, a)
    mc.setBlock(x+36,y+ 33,z+ 28, a)
    mc.setBlock(x+35,y+ 33,z+ 28, a)
    mc.setBlock(x+34,y+ 33,z+ 28, a)
    mc.setBlock(x+33,y+ 33,z+ 28, a)
    mc.setBlock(x+32,y+ 33,z+ 28, a)
    mc.setBlock(x+43,y+ 32,z+ 28, a)
    mc.setBlock(x+37,y+ 32,z+ 28, a)
    mc.setBlock(x+34,y+ 32,z+ 28, a)
    mc.setBlock(x+33,y+ 32,z+ 28, a)
    mc.setBlock(x+32,y+ 32,z+ 28, a)
    mc.setBlock(x+31,y+ 32,z+ 28, a)
    mc.setBlock(x+43,y+ 31,z+ 28, a)
    mc.setBlock(x+13,y+ 25,z+ 33, a)
    mc.setBlock(x+37,y+ 31,z+ 28, a)
    mc.setBlock(x+33,y+ 31,z+ 28, a)
    mc.setBlock(x+32,y+ 31,z+ 28, a)
    mc.setBlock(x+31,y+ 31,z+ 28, a)
    mc.setBlock(x+30,y+ 31,z+ 28, a)
    mc.setBlock(x+43,y+ 30,z+ 28, a)
    mc.setBlock(x+6,y+ 26,z+ 33, a)
    mc.setBlock(x+14,y+ 26,z+ 33, a)
    mc.setBlock(x+36,y+ 30,z+ 28, a)
    mc.setBlock(x+32,y+ 30,z+ 28, a)
    mc.setBlock(x+31,y+ 30,z+ 28, a)
    mc.setBlock(x+30,y+ 30,z+ 28, a)
    mc.setBlock(x+42,y+ 29,z+ 28, a)
    mc.setBlock(x+7,y+ 27,z+ 33, a)
    mc.setBlock(x+36,y+ 29,z+ 28, a)
    mc.setBlock(x+10,y+ 29,z+ 28, a)
    mc.setBlock(x+42,y+ 28,z+ 28, a)
    mc.setBlock(x+14,y+ 27,z+ 33, a)
    mc.setBlock(x+8,y+ 28,z+ 33, a)
    mc.setBlock(x+36,y+ 28,z+ 28, a)
    mc.setBlock(x+10,y+ 28,z+ 28, a)
    mc.setBlock(x+9,y+ 28,z+ 28, a)
    mc.setBlock(x+41,y+ 27,z+ 28, a)
    mc.setBlock(x+9,y+ 28,z+ 33, a)
    mc.setBlock(x+10,y+ 28,z+ 33, a)
    mc.setBlock(x+36,y+ 27,z+ 28, a)
    mc.setBlock(x+10,y+ 27,z+ 28, a)
    mc.setBlock(x+11,y+ 28,z+ 33, a)
    mc.setBlock(x+8,y+ 27,z+ 28, a)
    mc.setBlock(x+7,y+ 27,z+ 28, a)
    mc.setBlock(x+6,y+ 27,z+ 28, a)
    mc.setBlock(x+41,y+ 26,z+ 28, a)
    mc.setBlock(x+12,y+ 28,z+ 33, a)
    mc.setBlock(x+13,y+ 28,z+ 33, a)
    mc.setBlock(x+38,y+ 29,z+ 33, a)
    mc.setBlock(x+44,y+ 29,z+ 33, a)
    mc.setBlock(x+36,y+ 26,z+ 28, a)
    mc.setBlock(x+10,y+ 26,z+ 28, a)
    mc.setBlock(x+45,y+ 29,z+ 33, a)
    mc.setBlock(x+38,y+ 30,z+ 33, a)
    mc.setBlock(x+44,y+ 30,z+ 33, a)
    mc.setBlock(x+5,y+ 26,z+ 28, a)
    mc.setBlock(x+2,y+ 26,z+ 28, a)
    mc.setBlock(x+1,y+ 26,z+ 28, a)
    mc.setBlock(x+40,y+ 25,z+ 28, a)
    mc.setBlock(x+39,y+ 25,z+ 28, a)
    mc.setBlock(x+38,y+ 25,z+ 28, a)
    mc.setBlock(x+37,y+ 25,z+ 28, a)
    mc.setBlock(x+11,y+ 25,z+ 28, a)
    mc.setBlock(x+45,y+ 30,z+ 33, a)
    mc.setBlock(x+38,y+ 31,z+ 33, a)
    mc.setBlock(x+4,y+ 25,z+ 28, a)
    mc.setBlock(x+3,y+ 25,z+ 28, a)
    mc.setBlock(x+2,y+ 25,z+ 28, a)
    mc.setBlock(x+1,y+ 25,z+ 28, a)
    mc.setBlock(x+11,y+ 24,z+ 28, a)
    mc.setBlock(x+44,y+ 31,z+ 33, a)
    mc.setBlock(x+45,y+ 31,z+ 33, a)
    mc.setBlock(x+3,y+ 24,z+ 28, a)
    mc.setBlock(x+11,y+ 23,z+ 28, a)
    mc.setBlock(x+38,y+ 32,z+ 33, a)
    mc.setBlock(x+4,y+ 23,z+ 28, a)
    mc.setBlock(x+12,y+ 22,z+ 28, a)
    mc.setBlock(x+45,y+ 32,z+ 33, a)
    mc.setBlock(x+38,y+ 33,z+ 33, a)
    mc.setBlock(x+4,y+ 22,z+ 28, a)
    mc.setBlock(x+14,y+ 21,z+ 28, a)
    mc.setBlock(x+13,y+ 21,z+ 28, a)
    mc.setBlock(x+12,y+ 21,z+ 28, a)
    mc.setBlock(x+11,y+ 21,z+ 28, a)
    mc.setBlock(x+10,y+ 21,z+ 28, a)
    mc.setBlock(x+45,y+ 33,z+ 33, a)
    mc.setBlock(x+38,y+ 34,z+ 33, a)
    mc.setBlock(x+4,y+ 21,z+ 28, a)
    mc.setBlock(x+14,y+ 20,z+ 28, a)
    mc.setBlock(x+13,y+ 20,z+ 28, a)
    mc.setBlock(x+9,y+ 20,z+ 28, a)
    mc.setBlock(x+8,y+ 20,z+ 28, a)
    mc.setBlock(x+45,y+ 34,z+ 33, a)
    mc.setBlock(x+38,y+ 35,z+ 33, a)
    mc.setBlock(x+5,y+ 20,z+ 28, a)
    mc.setBlock(x+7,y+ 19,z+ 28, a)
    mc.setBlock(x+6,y+ 19,z+ 28, a)
    mc.setBlock(x+5,y+ 19,z+ 28, a)
    mc.setBlock(x+5,y+ 18,z+ 28, a)
    mc.setBlock(x+5,y+ 17,z+ 28, a)
    mc.setBlock(x+4,y+ 17,z+ 28, a)
    mc.setBlock(x+5,y+ 16,z+ 28, a)
    mc.setBlock(x+4,y+ 16,z+ 28, a)
    mc.setBlock(x+4,y+ 15,z+ 28, a)
    mc.setBlock(x+40,y+ 43,z+ 27, a)
    mc.setBlock(x+39,y+ 43,z+ 27, a)
    mc.setBlock(x+38,y+ 43,z+ 27, a)
    mc.setBlock(x+41,y+ 42,z+ 27, a)
    mc.setBlock(x+40,y+ 42,z+ 27, a)
    mc.setBlock(x+39,y+ 42,z+ 27, a)
    mc.setBlock(x+38,y+ 42,z+ 27, a)
    mc.setBlock(x+42,y+ 41,z+ 27, a)
    mc.setBlock(x+41,y+ 41,z+ 27, a)
    mc.setBlock(x+40,y+ 41,z+ 27, a)
    mc.setBlock(x+39,y+ 41,z+ 27, a)
    mc.setBlock(x+38,y+ 41,z+ 27, a)
    mc.setBlock(x+42,y+ 40,z+ 27, a)
    mc.setBlock(x+38,y+ 36,z+ 33, a)
    mc.setBlock(x+38,y+ 37,z+ 33, a)
    mc.setBlock(x+38,y+ 38,z+ 33, a)
    mc.setBlock(x+6,y+ 18,z+ 34, a)
    mc.setBlock(x+37,y+ 40,z+ 27, a)
    mc.setBlock(x+43,y+ 39,z+ 27, a)
    mc.setBlock(x+6,y+ 19,z+ 34, a)
    mc.setBlock(x+37,y+ 39,z+ 27, a)
    mc.setBlock(x+43,y+ 38,z+ 27, a)
    mc.setBlock(x+8,y+ 22,z+ 34, a)
    mc.setBlock(x+37,y+ 38,z+ 27, a)
    mc.setBlock(x+43,y+ 37,z+ 27, a)
    mc.setBlock(x+7,y+ 23,z+ 34, a)
    mc.setBlock(x+8,y+ 23,z+ 34, a)
    mc.setBlock(x+36,y+ 37,z+ 27, a)
    mc.setBlock(x+44,y+ 36,z+ 27, a)
    mc.setBlock(x+9,y+ 23,z+ 34, a)
    mc.setBlock(x+10,y+ 23,z+ 34, a)
    mc.setBlock(x+11,y+ 23,z+ 34, a)
    mc.setBlock(x+35,y+ 36,z+ 27, a)
    mc.setBlock(x+44,y+ 35,z+ 27, a)
    mc.setBlock(x+12,y+ 23,z+ 34, a)
    mc.setBlock(x+7,y+ 24,z+ 34, a)
    mc.setBlock(x+35,y+ 35,z+ 27, a)
    mc.setBlock(x+44,y+ 34,z+ 27, a)
    mc.setBlock(x+13,y+ 24,z+ 34, a)
    mc.setBlock(x+14,y+ 24,z+ 34, a)
    mc.setBlock(x+7,y+ 25,z+ 34, a)
    mc.setBlock(x+14,y+ 25,z+ 34, a)
    mc.setBlock(x+34,y+ 34,z+ 27, a)
    mc.setBlock(x+46,y+ 33,z+ 27, a)
    mc.setBlock(x+45,y+ 33,z+ 27, a)
    mc.setBlock(x+43,y+ 33,z+ 27, a)
    mc.setBlock(x+7,y+ 26,z+ 34, a)
    mc.setBlock(x+15,y+ 26,z+ 34, a)
    mc.setBlock(x+35,y+ 33,z+ 27, a)
    mc.setBlock(x+34,y+ 33,z+ 27, a)
    mc.setBlock(x+33,y+ 33,z+ 27, a)
    mc.setBlock(x+47,y+ 32,z+ 27, a)
    mc.setBlock(x+46,y+ 32,z+ 27, a)
    mc.setBlock(x+45,y+ 32,z+ 27, a)
    mc.setBlock(x+43,y+ 32,z+ 27, a)
    mc.setBlock(x+8,y+ 27,z+ 34, a)
    mc.setBlock(x+36,y+ 32,z+ 27, a)
    mc.setBlock(x+35,y+ 32,z+ 27, a)
    mc.setBlock(x+34,y+ 32,z+ 27, a)
    mc.setBlock(x+33,y+ 32,z+ 27, a)
    mc.setBlock(x+32,y+ 32,z+ 27, a)
    mc.setBlock(x+31,y+ 32,z+ 27, a)
    mc.setBlock(x+48,y+ 31,z+ 27, a)
    mc.setBlock(x+47,y+ 31,z+ 27, a)
    mc.setBlock(x+46,y+ 31,z+ 27, a)
    mc.setBlock(x+43,y+ 31,z+ 27, a)
    mc.setBlock(x+14,y+ 27,z+ 34, a)
    mc.setBlock(x+36,y+ 31,z+ 27, a)
    mc.setBlock(x+33,y+ 31,z+ 27, a)
    mc.setBlock(x+9,y+ 28,z+ 34, a)
    mc.setBlock(x+10,y+ 28,z+ 34, a)
    mc.setBlock(x+30,y+ 31,z+ 27, a)
    mc.setBlock(x+48,y+ 30,z+ 27, a)
    mc.setBlock(x+47,y+ 30,z+ 27, a)
    mc.setBlock(x+43,y+ 30,z+ 27, a)
    mc.setBlock(x+13,y+ 28,z+ 34, a)
    mc.setBlock(x+36,y+ 30,z+ 27, a)
    mc.setBlock(x+32,y+ 30,z+ 27, a)
    mc.setBlock(x+14,y+ 28,z+ 34, a)
    mc.setBlock(x+11,y+ 29,z+ 34, a)
    mc.setBlock(x+29,y+ 30,z+ 27, a)
    mc.setBlock(x+10,y+ 30,z+ 27, a)
    mc.setBlock(x+43,y+ 29,z+ 27, a)
    mc.setBlock(x+12,y+ 29,z+ 34, a)
    mc.setBlock(x+36,y+ 29,z+ 27, a)
    mc.setBlock(x+31,y+ 29,z+ 27, a)
    mc.setBlock(x+30,y+ 29,z+ 27, a)
    mc.setBlock(x+29,y+ 29,z+ 27, a)
    mc.setBlock(x+10,y+ 29,z+ 27, a)
    mc.setBlock(x+9,y+ 29,z+ 27, a)
    mc.setBlock(x+42,y+ 28,z+ 27, a)
    mc.setBlock(x+36,y+ 28,z+ 27, a)
    mc.setBlock(x+10,y+ 28,z+ 27, a)
    mc.setBlock(x+9,y+ 28,z+ 27, a)
    mc.setBlock(x+42,y+ 27,z+ 27, a)
    mc.setBlock(x+38,y+ 29,z+ 34, a)
    mc.setBlock(x+37,y+ 30,z+ 34, a)
    mc.setBlock(x+35,y+ 27,z+ 27, a)
    mc.setBlock(x+9,y+ 27,z+ 27, a)
    mc.setBlock(x+41,y+ 26,z+ 27, a)
    mc.setBlock(x+38,y+ 30,z+ 34, a)
    mc.setBlock(x+36,y+ 26,z+ 27, a)
    mc.setBlock(x+10,y+ 26,z+ 27, a)
    mc.setBlock(x+37,y+ 31,z+ 34, a)
    mc.setBlock(x+8,y+ 26,z+ 27, a)
    mc.setBlock(x+7,y+ 26,z+ 27, a)
    mc.setBlock(x+6,y+ 26,z+ 27, a)
    mc.setBlock(x+5,y+ 26,z+ 27, a)
    mc.setBlock(x+41,y+ 25,z+ 27, a)
    mc.setBlock(x+38,y+ 31,z+ 34, a)
    mc.setBlock(x+38,y+ 32,z+ 34, a)
    mc.setBlock(x+38,y+ 33,z+ 34, a)
    mc.setBlock(x+38,y+ 34,z+ 34, a)
    mc.setBlock(x+36,y+ 25,z+ 27, a)
    mc.setBlock(x+10,y+ 25,z+ 27, a)
    mc.setBlock(x+38,y+ 35,z+ 34, a)
    mc.setBlock(x+38,y+ 36,z+ 34, a)
    mc.setBlock(x+4,y+ 25,z+ 27, a)
    mc.setBlock(x+3,y+ 25,z+ 27, a)
    mc.setBlock(x+2,y+ 25,z+ 27, a)
    mc.setBlock(x+1,y+ 25,z+ 27, a)
    mc.setBlock(x+0,y+ 25,z+ 27, a)
    mc.setBlock(x+40,y+ 24,z+ 27, a)
    mc.setBlock(x+39,y+ 24,z+ 27, a)
    mc.setBlock(x+38,y+ 24,z+ 27, a)
    mc.setBlock(x+37,y+ 24,z+ 27, a)
    mc.setBlock(x+36,y+ 24,z+ 27, a)
    mc.setBlock(x+11,y+ 24,z+ 27, a)
    mc.setBlock(x+38,y+ 37,z+ 34, a)
    mc.setBlock(x+38,y+ 38,z+ 34, a)
    mc.setBlock(x+3,y+ 24,z+ 27, a)
    mc.setBlock(x+2,y+ 24,z+ 27, a)
    mc.setBlock(x+38,y+ 23,z+ 27, a)
    mc.setBlock(x+37,y+ 23,z+ 27, a)
    mc.setBlock(x+11,y+ 23,z+ 27, a)
    mc.setBlock(x+9,y+ 23,z+ 35, a)
    mc.setBlock(x+4,y+ 23,z+ 27, a)
    mc.setBlock(x+11,y+ 22,z+ 27, a)
    mc.setBlock(x+10,y+ 23,z+ 35, a)
    mc.setBlock(x+4,y+ 22,z+ 27, a)
    mc.setBlock(x+14,y+ 21,z+ 27, a)
    mc.setBlock(x+13,y+ 21,z+ 27, a)
    mc.setBlock(x+12,y+ 21,z+ 27, a)
    mc.setBlock(x+11,y+ 21,z+ 27, a)
    mc.setBlock(x+10,y+ 21,z+ 27, a)
    mc.setBlock(x+11,y+ 23,z+ 35, a)
    mc.setBlock(x+4,y+ 21,z+ 27, a)
    mc.setBlock(x+14,y+ 20,z+ 27, a)
    mc.setBlock(x+13,y+ 20,z+ 27, a)
    mc.setBlock(x+12,y+ 20,z+ 27, a)
    mc.setBlock(x+9,y+ 20,z+ 27, a)
    mc.setBlock(x+12,y+ 23,z+ 35, a)
    mc.setBlock(x+8,y+ 24,z+ 35, a)
    mc.setBlock(x+13,y+ 24,z+ 35, a)
    mc.setBlock(x+4,y+ 20,z+ 27, a)
    mc.setBlock(x+8,y+ 19,z+ 27, a)
    mc.setBlock(x+7,y+ 19,z+ 27, a)
    mc.setBlock(x+14,y+ 24,z+ 35, a)
    mc.setBlock(x+5,y+ 19,z+ 27, a)
    mc.setBlock(x+6,y+ 18,z+ 27, a)
    mc.setBlock(x+5,y+ 18,z+ 27, a)
    mc.setBlock(x+5,y+ 17,z+ 27, a)
    mc.setBlock(x+4,y+ 17,z+ 27, a)
    mc.setBlock(x+5,y+ 16,z+ 27, a)
    mc.setBlock(x+4,y+ 16,z+ 27, a)
    mc.setBlock(x+4,y+ 15,z+ 27, a)
    mc.setBlock(x+40,y+ 45,z+ 26, a)
    mc.setBlock(x+39,y+ 45,z+ 26, a)
    mc.setBlock(x+38,y+ 45,z+ 26, a)
    mc.setBlock(x+41,y+ 44,z+ 26, a)
    mc.setBlock(x+40,y+ 44,z+ 26, a)
    mc.setBlock(x+39,y+ 44,z+ 26, a)
    mc.setBlock(x+38,y+ 44,z+ 26, a)
    mc.setBlock(x+37,y+ 44,z+ 26, a)
    mc.setBlock(x+41,y+ 43,z+ 26, a)
    mc.setBlock(x+8,y+ 25,z+ 35, a)
    mc.setBlock(x+15,y+ 25,z+ 35, a)
    mc.setBlock(x+8,y+ 26,z+ 35, a)
    mc.setBlock(x+37,y+ 43,z+ 26, a)
    mc.setBlock(x+42,y+ 42,z+ 26, a)
    mc.setBlock(x+16,y+ 26,z+ 35, a)
    mc.setBlock(x+8,y+ 27,z+ 35, a)
    mc.setBlock(x+15,y+ 27,z+ 35, a)
    mc.setBlock(x+37,y+ 42,z+ 26, a)
    mc.setBlock(x+42,y+ 41,z+ 26, a)
    mc.setBlock(x+16,y+ 27,z+ 35, a)
    mc.setBlock(x+9,y+ 28,z+ 35, a)
    mc.setBlock(x+37,y+ 41,z+ 26, a)
    mc.setBlock(x+42,y+ 40,z+ 26, a)
    mc.setBlock(x+10,y+ 28,z+ 35, a)
    mc.setBlock(x+37,y+ 40,z+ 26, a)
    mc.setBlock(x+43,y+ 39,z+ 26, a)
    mc.setBlock(x+15,y+ 28,z+ 35, a)
    mc.setBlock(x+11,y+ 29,z+ 35, a)
    mc.setBlock(x+36,y+ 39,z+ 26, a)
    mc.setBlock(x+43,y+ 38,z+ 26, a)
    mc.setBlock(x+12,y+ 29,z+ 35, a)
    mc.setBlock(x+36,y+ 38,z+ 26, a)
    mc.setBlock(x+43,y+ 37,z+ 26, a)
    mc.setBlock(x+13,y+ 29,z+ 35, a)
    mc.setBlock(x+14,y+ 29,z+ 35, a)
    mc.setBlock(x+36,y+ 37,z+ 26, a)
    mc.setBlock(x+44,y+ 36,z+ 26, a)
    mc.setBlock(x+37,y+ 30,z+ 35, a)
    mc.setBlock(x+38,y+ 30,z+ 35, a)
    mc.setBlock(x+37,y+ 31,z+ 35, a)
    mc.setBlock(x+38,y+ 31,z+ 35, a)
    mc.setBlock(x+35,y+ 36,z+ 26, a)
    mc.setBlock(x+44,y+ 35,z+ 26, a)
    mc.setBlock(x+38,y+ 32,z+ 35, a)
    mc.setBlock(x+35,y+ 35,z+ 26, a)
    mc.setBlock(x+45,y+ 34,z+ 26, a)
    mc.setBlock(x+38,y+ 33,z+ 35, a)
    mc.setBlock(x+10,y+ 23,z+ 36, a)
    mc.setBlock(x+11,y+ 23,z+ 36, a)
    mc.setBlock(x+12,y+ 23,z+ 36, a)
    mc.setBlock(x+35,y+ 34,z+ 26, a)
    mc.setBlock(x+46,y+ 33,z+ 26, a)
    mc.setBlock(x+9,y+ 24,z+ 36, a)
    mc.setBlock(x+44,y+ 33,z+ 26, a)
    mc.setBlock(x+13,y+ 24,z+ 36, a)
    mc.setBlock(x+14,y+ 24,z+ 36, a)
    mc.setBlock(x+15,y+ 24,z+ 36, a)
    mc.setBlock(x+36,y+ 33,z+ 26, a)
    mc.setBlock(x+48,y+ 32,z+ 26, a)
    mc.setBlock(x+47,y+ 32,z+ 26, a)
    mc.setBlock(x+9,y+ 25,z+ 36, a)
    mc.setBlock(x+16,y+ 25,z+ 36, a)
    mc.setBlock(x+44,y+ 32,z+ 26, a)
    mc.setBlock(x+9,y+ 26,z+ 36, a)
    mc.setBlock(x+37,y+ 32,z+ 26, a)
    mc.setBlock(x+48,y+ 31,z+ 26, a)
    mc.setBlock(x+17,y+ 26,z+ 36, a)
    mc.setBlock(x+45,y+ 31,z+ 26, a)
    mc.setBlock(x+43,y+ 31,z+ 26, a)
    mc.setBlock(x+9,y+ 27,z+ 36, a)
    mc.setBlock(x+17,y+ 27,z+ 36, a)
    mc.setBlock(x+36,y+ 31,z+ 26, a)
    mc.setBlock(x+32,y+ 31,z+ 26, a)
    mc.setBlock(x+31,y+ 31,z+ 26, a)
    mc.setBlock(x+30,y+ 31,z+ 26, a)
    mc.setBlock(x+29,y+ 31,z+ 26, a)
    mc.setBlock(x+48,y+ 30,z+ 26, a)
    mc.setBlock(x+47,y+ 30,z+ 26, a)
    mc.setBlock(x+46,y+ 30,z+ 26, a)
    mc.setBlock(x+43,y+ 30,z+ 26, a)
    mc.setBlock(x+9,y+ 28,z+ 36, a)
    mc.setBlock(x+36,y+ 30,z+ 26, a)
    mc.setBlock(x+32,y+ 30,z+ 26, a)
    mc.setBlock(x+31,y+ 30,z+ 26, a)
    mc.setBlock(x+10,y+ 28,z+ 36, a)
    mc.setBlock(x+16,y+ 28,z+ 36, a)
    mc.setBlock(x+28,y+ 30,z+ 26, a)
    mc.setBlock(x+10,y+ 30,z+ 26, a)
    mc.setBlock(x+48,y+ 29,z+ 26, a)
    mc.setBlock(x+43,y+ 29,z+ 26, a)
    mc.setBlock(x+17,y+ 28,z+ 36, a)
    mc.setBlock(x+36,y+ 29,z+ 26, a)
    mc.setBlock(x+31,y+ 29,z+ 26, a)
    mc.setBlock(x+30,y+ 29,z+ 26, a)
    mc.setBlock(x+11,y+ 29,z+ 36, a)
    mc.setBlock(x+28,y+ 29,z+ 26, a)
    mc.setBlock(x+10,y+ 29,z+ 26, a)
    mc.setBlock(x+9,y+ 29,z+ 26, a)
    mc.setBlock(x+42,y+ 28,z+ 26, a)
    mc.setBlock(x+12,y+ 29,z+ 36, a)
    mc.setBlock(x+35,y+ 28,z+ 26, a)
    mc.setBlock(x+29,y+ 28,z+ 26, a)
    mc.setBlock(x+28,y+ 28,z+ 26, a)
    mc.setBlock(x+9,y+ 28,z+ 26, a)
    mc.setBlock(x+42,y+ 27,z+ 26, a)
    mc.setBlock(x+13,y+ 29,z+ 36, a)
    mc.setBlock(x+35,y+ 27,z+ 26, a)
    mc.setBlock(x+9,y+ 27,z+ 26, a)
    mc.setBlock(x+42,y+ 26,z+ 26, a)
    mc.setBlock(x+14,y+ 29,z+ 36, a)
    mc.setBlock(x+15,y+ 29,z+ 36, a)
    mc.setBlock(x+35,y+ 26,z+ 26, a)
    mc.setBlock(x+9,y+ 26,z+ 26, a)
    mc.setBlock(x+8,y+ 26,z+ 26, a)
    mc.setBlock(x+7,y+ 26,z+ 26, a)
    mc.setBlock(x+6,y+ 26,z+ 26, a)
    mc.setBlock(x+41,y+ 25,z+ 26, a)
    mc.setBlock(x+16,y+ 29,z+ 36, a)
    mc.setBlock(x+10,y+ 24,z+ 37, a)
    mc.setBlock(x+35,y+ 25,z+ 26, a)
    mc.setBlock(x+10,y+ 25,z+ 26, a)
    mc.setBlock(x+11,y+ 24,z+ 37, a)
    mc.setBlock(x+12,y+ 24,z+ 37, a)
    mc.setBlock(x+13,y+ 24,z+ 37, a)
    mc.setBlock(x+5,y+ 25,z+ 26, a)
    mc.setBlock(x+4,y+ 25,z+ 26, a)
    mc.setBlock(x+2,y+ 25,z+ 26, a)
    mc.setBlock(x+1,y+ 25,z+ 26, a)
    mc.setBlock(x+0,y+ 25,z+ 26, a)
    mc.setBlock(x+40,y+ 24,z+ 26, a)
    mc.setBlock(x+14,y+ 24,z+ 37, a)
    mc.setBlock(x+15,y+ 24,z+ 37, a)
    mc.setBlock(x+35,y+ 24,z+ 26, a)
    mc.setBlock(x+10,y+ 24,z+ 26, a)
    mc.setBlock(x+16,y+ 24,z+ 37, a)
    mc.setBlock(x+9,y+ 25,z+ 37, a)
    mc.setBlock(x+3,y+ 24,z+ 26, a)
    mc.setBlock(x+2,y+ 24,z+ 26, a)
    mc.setBlock(x+1,y+ 24,z+ 26, a)
    mc.setBlock(x+0,y+ 24,z+ 26, a)
    mc.setBlock(x+40,y+ 23,z+ 26, a)
    mc.setBlock(x+39,y+ 23,z+ 26, a)
    mc.setBlock(x+17,y+ 25,z+ 37, a)
    mc.setBlock(x+18,y+ 25,z+ 37, a)
    mc.setBlock(x+36,y+ 23,z+ 26, a)
    mc.setBlock(x+35,y+ 23,z+ 26, a)
    mc.setBlock(x+10,y+ 23,z+ 26, a)
    mc.setBlock(x+9,y+ 26,z+ 37, a)
    mc.setBlock(x+3,y+ 23,z+ 26, a)
    mc.setBlock(x+39,y+ 22,z+ 26, a)
    mc.setBlock(x+38,y+ 22,z+ 26, a)
    mc.setBlock(x+37,y+ 22,z+ 26, a)
    mc.setBlock(x+36,y+ 22,z+ 26, a)
    mc.setBlock(x+10,y+ 22,z+ 26, a)
    mc.setBlock(x+4,y+ 22,z+ 26, a)
    mc.setBlock(x+12,y+ 21,z+ 26, a)
    mc.setBlock(x+11,y+ 21,z+ 26, a)
    mc.setBlock(x+18,y+ 26,z+ 37, a)
    mc.setBlock(x+4,y+ 21,z+ 26, a)
    mc.setBlock(x+14,y+ 20,z+ 26, a)
    mc.setBlock(x+13,y+ 20,z+ 26, a)
    mc.setBlock(x+12,y+ 20,z+ 26, a)
    mc.setBlock(x+11,y+ 20,z+ 26, a)
    mc.setBlock(x+10,y+ 20,z+ 26, a)
    mc.setBlock(x+19,y+ 26,z+ 37, a)
    mc.setBlock(x+10,y+ 27,z+ 37, a)
    mc.setBlock(x+4,y+ 20,z+ 26, a)
    mc.setBlock(x+13,y+ 19,z+ 26, a)
    mc.setBlock(x+9,y+ 19,z+ 26, a)
    mc.setBlock(x+8,y+ 19,z+ 26, a)
    mc.setBlock(x+18,y+ 27,z+ 37, a)
    mc.setBlock(x+19,y+ 27,z+ 37, a)
    mc.setBlock(x+10,y+ 28,z+ 37, a)
    mc.setBlock(x+4,y+ 19,z+ 26, a)
    mc.setBlock(x+7,y+ 18,z+ 26, a)
    mc.setBlock(x+6,y+ 18,z+ 26, a)
    mc.setBlock(x+5,y+ 18,z+ 26, a)
    mc.setBlock(x+5,y+ 17,z+ 26, a)
    mc.setBlock(x+5,y+ 16,z+ 26, a)
    mc.setBlock(x+4,y+ 16,z+ 26, a)
    mc.setBlock(x+38,y+ 47,z+ 25, a)
    mc.setBlock(x+37,y+ 47,z+ 25, a)
    mc.setBlock(x+40,y+ 46,z+ 25, a)
    mc.setBlock(x+39,y+ 46,z+ 25, a)
    mc.setBlock(x+38,y+ 46,z+ 25, a)
    mc.setBlock(x+37,y+ 46,z+ 25, a)
    mc.setBlock(x+36,y+ 46,z+ 25, a)
    mc.setBlock(x+41,y+ 45,z+ 25, a)
    mc.setBlock(x+18,y+ 28,z+ 37, a)
    mc.setBlock(x+19,y+ 28,z+ 37, a)
    mc.setBlock(x+27,y+ 28,z+ 37, a)
    mc.setBlock(x+37,y+ 45,z+ 25, a)
    mc.setBlock(x+36,y+ 45,z+ 25, a)
    mc.setBlock(x+41,y+ 44,z+ 25, a)
    mc.setBlock(x+28,y+ 28,z+ 37, a)
    mc.setBlock(x+29,y+ 28,z+ 37, a)
    mc.setBlock(x+36,y+ 44,z+ 25, a)
    mc.setBlock(x+42,y+ 43,z+ 25, a)
    mc.setBlock(x+30,y+ 28,z+ 37, a)
    mc.setBlock(x+31,y+ 28,z+ 37, a)
    mc.setBlock(x+36,y+ 43,z+ 25, a)
    mc.setBlock(x+42,y+ 42,z+ 25, a)
    mc.setBlock(x+11,y+ 29,z+ 37, a)
    mc.setBlock(x+36,y+ 42,z+ 25, a)
    mc.setBlock(x+42,y+ 41,z+ 25, a)
    mc.setBlock(x+37,y+ 41,z+ 25, a)
    mc.setBlock(x+42,y+ 40,z+ 25, a)
    mc.setBlock(x+37,y+ 40,z+ 25, a)
    mc.setBlock(x+43,y+ 39,z+ 25, a)
    mc.setBlock(x+12,y+ 29,z+ 37, a)
    mc.setBlock(x+13,y+ 29,z+ 37, a)
    mc.setBlock(x+36,y+ 39,z+ 25, a)
    mc.setBlock(x+43,y+ 38,z+ 25, a)
    mc.setBlock(x+14,y+ 29,z+ 37, a)
    mc.setBlock(x+36,y+ 38,z+ 25, a)
    mc.setBlock(x+43,y+ 37,z+ 25, a)
    mc.setBlock(x+15,y+ 29,z+ 37, a)
    mc.setBlock(x+16,y+ 29,z+ 37, a)
    mc.setBlock(x+36,y+ 37,z+ 25, a)
    mc.setBlock(x+44,y+ 36,z+ 25, a)
    mc.setBlock(x+17,y+ 29,z+ 37, a)
    mc.setBlock(x+18,y+ 29,z+ 37, a)
    mc.setBlock(x+27,y+ 29,z+ 37, a)
    mc.setBlock(x+36,y+ 36,z+ 25, a)
    mc.setBlock(x+44,y+ 35,z+ 25, a)
    mc.setBlock(x+28,y+ 29,z+ 37, a)
    mc.setBlock(x+36,y+ 35,z+ 25, a)
    mc.setBlock(x+45,y+ 34,z+ 25, a)
    mc.setBlock(x+29,y+ 29,z+ 37, a)
    mc.setBlock(x+24,y+ 20,z+ 38, a)
    mc.setBlock(x+25,y+ 20,z+ 38, a)
    mc.setBlock(x+11,y+ 24,z+ 38, a)
    mc.setBlock(x+12,y+ 24,z+ 38, a)
    mc.setBlock(x+36,y+ 34,z+ 25, a)
    mc.setBlock(x+46,y+ 33,z+ 25, a)
    mc.setBlock(x+45,y+ 33,z+ 25, a)
    mc.setBlock(x+44,y+ 33,z+ 25, a)
    mc.setBlock(x+43,y+ 33,z+ 25, a)
    mc.setBlock(x+13,y+ 24,z+ 38, a)
    mc.setBlock(x+14,y+ 24,z+ 38, a)
    mc.setBlock(x+15,y+ 24,z+ 38, a)
    mc.setBlock(x+37,y+ 33,z+ 25, a)
    mc.setBlock(x+47,y+ 32,z+ 25, a)
    mc.setBlock(x+46,y+ 32,z+ 25, a)
    mc.setBlock(x+45,y+ 32,z+ 25, a)
    mc.setBlock(x+43,y+ 32,z+ 25, a)
    mc.setBlock(x+16,y+ 24,z+ 38, a)
    mc.setBlock(x+17,y+ 24,z+ 38, a)
    mc.setBlock(x+10,y+ 25,z+ 38, a)
    mc.setBlock(x+37,y+ 32,z+ 25, a)
    mc.setBlock(x+48,y+ 31,z+ 25, a)
    mc.setBlock(x+11,y+ 25,z+ 38, a)
    mc.setBlock(x+46,y+ 31,z+ 25, a)
    mc.setBlock(x+43,y+ 31,z+ 25, a)
    mc.setBlock(x+18,y+ 25,z+ 38, a)
    mc.setBlock(x+19,y+ 25,z+ 38, a)
    mc.setBlock(x+20,y+ 25,z+ 38, a)
    mc.setBlock(x+37,y+ 31,z+ 25, a)
    mc.setBlock(x+49,y+ 30,z+ 25, a)
    mc.setBlock(x+10,y+ 26,z+ 38, a)
    mc.setBlock(x+20,y+ 26,z+ 38, a)
    mc.setBlock(x+46,y+ 30,z+ 25, a)
    mc.setBlock(x+42,y+ 30,z+ 25, a)
    mc.setBlock(x+21,y+ 26,z+ 38, a)
    mc.setBlock(x+36,y+ 30,z+ 25, a)
    mc.setBlock(x+30,y+ 30,z+ 25, a)
    mc.setBlock(x+29,y+ 30,z+ 25, a)
    mc.setBlock(x+28,y+ 30,z+ 25, a)
    mc.setBlock(x+27,y+ 30,z+ 25, a)
    mc.setBlock(x+26,y+ 30,z+ 25, a)
    mc.setBlock(x+25,y+ 30,z+ 25, a)
    mc.setBlock(x+10,y+ 30,z+ 25, a)
    mc.setBlock(x+48,y+ 29,z+ 25, a)
    mc.setBlock(x+47,y+ 29,z+ 25, a)
    mc.setBlock(x+42,y+ 29,z+ 25, a)
    mc.setBlock(x+36,y+ 29,z+ 25, a)
    mc.setBlock(x+30,y+ 29,z+ 25, a)
    mc.setBlock(x+33,y+ 26,z+ 38, a)
    mc.setBlock(x+34,y+ 26,z+ 38, a)
    mc.setBlock(x+27,y+ 29,z+ 25, a)
    mc.setBlock(x+26,y+ 29,z+ 25, a)
    mc.setBlock(x+25,y+ 29,z+ 25, a)
    mc.setBlock(x+10,y+ 29,z+ 25, a)
    mc.setBlock(x+9,y+ 29,z+ 25, a)
    mc.setBlock(x+42,y+ 28,z+ 25, a)
    mc.setBlock(x+10,y+ 27,z+ 38, a)
    mc.setBlock(x+20,y+ 27,z+ 38, a)
    mc.setBlock(x+35,y+ 28,z+ 25, a)
    mc.setBlock(x+30,y+ 28,z+ 25, a)
    mc.setBlock(x+29,y+ 28,z+ 25, a)
    mc.setBlock(x+28,y+ 28,z+ 25, a)
    mc.setBlock(x+27,y+ 28,z+ 25, a)
    mc.setBlock(x+26,y+ 28,z+ 25, a)
    mc.setBlock(x+25,y+ 28,z+ 25, a)
    mc.setBlock(x+9,y+ 28,z+ 25, a)
    mc.setBlock(x+42,y+ 27,z+ 25, a)
    mc.setBlock(x+21,y+ 27,z+ 38, a)
    mc.setBlock(x+29,y+ 27,z+ 38, a)
    mc.setBlock(x+35,y+ 27,z+ 25, a)
    mc.setBlock(x+9,y+ 27,z+ 25, a)
    mc.setBlock(x+8,y+ 27,z+ 25, a)
    mc.setBlock(x+42,y+ 26,z+ 25, a)
    mc.setBlock(x+30,y+ 27,z+ 38, a)
    mc.setBlock(x+31,y+ 27,z+ 38, a)
    mc.setBlock(x+35,y+ 26,z+ 25, a)
    mc.setBlock(x+9,y+ 26,z+ 25, a)
    mc.setBlock(x+32,y+ 27,z+ 38, a)
    mc.setBlock(x+7,y+ 26,z+ 25, a)
    mc.setBlock(x+41,y+ 25,z+ 25, a)
    mc.setBlock(x+33,y+ 27,z+ 38, a)
    mc.setBlock(x+35,y+ 25,z+ 25, a)
    mc.setBlock(x+9,y+ 25,z+ 25, a)
    mc.setBlock(x+34,y+ 27,z+ 38, a)
    mc.setBlock(x+11,y+ 28,z+ 38, a)
    mc.setBlock(x+6,y+ 25,z+ 25, a)
    mc.setBlock(x+5,y+ 25,z+ 25, a)
    mc.setBlock(x+1,y+ 25,z+ 25, a)
    mc.setBlock(x+0,y+ 25,z+ 25, a)
    mc.setBlock(x+40,y+ 24,z+ 25, a)
    mc.setBlock(x+35,y+ 24,z+ 25, a)
    mc.setBlock(x+10,y+ 24,z+ 25, a)
    mc.setBlock(x+20,y+ 28,z+ 38, a)
    mc.setBlock(x+26,y+ 28,z+ 38, a)
    mc.setBlock(x+4,y+ 24,z+ 25, a)
    mc.setBlock(x+3,y+ 24,z+ 25, a)
    mc.setBlock(x+2,y+ 24,z+ 25, a)
    mc.setBlock(x+27,y+ 28,z+ 38, a)
    mc.setBlock(x+0,y+ 24,z+ 25, a)
    mc.setBlock(x+40,y+ 23,z+ 25, a)
    mc.setBlock(x+28,y+ 28,z+ 38, a)
    mc.setBlock(x+30,y+ 28,z+ 38, a)
    mc.setBlock(x+34,y+ 23,z+ 25, a)
    mc.setBlock(x+10,y+ 23,z+ 25, a)
    mc.setBlock(x+31,y+ 28,z+ 38, a)
    mc.setBlock(x+32,y+ 28,z+ 38, a)
    mc.setBlock(x+12,y+ 29,z+ 38, a)
    mc.setBlock(x+2,y+ 23,z+ 25, a)
    mc.setBlock(x+1,y+ 23,z+ 25, a)
    mc.setBlock(x+39,y+ 22,z+ 25, a)
    mc.setBlock(x+13,y+ 29,z+ 38, a)
    mc.setBlock(x+14,y+ 29,z+ 38, a)
    mc.setBlock(x+15,y+ 29,z+ 38, a)
    mc.setBlock(x+35,y+ 22,z+ 25, a)
    mc.setBlock(x+10,y+ 22,z+ 25, a)
    mc.setBlock(x+16,y+ 29,z+ 38, a)
    mc.setBlock(x+3,y+ 22,z+ 25, a)
    mc.setBlock(x+38,y+ 21,z+ 25, a)
    mc.setBlock(x+37,y+ 21,z+ 25, a)
    mc.setBlock(x+36,y+ 21,z+ 25, a)
    mc.setBlock(x+35,y+ 21,z+ 25, a)
    mc.setBlock(x+11,y+ 21,z+ 25, a)
    mc.setBlock(x+17,y+ 29,z+ 38, a)
    mc.setBlock(x+18,y+ 29,z+ 38, a)
    mc.setBlock(x+3,y+ 21,z+ 25, a)
    mc.setBlock(x+13,y+ 20,z+ 25, a)
    mc.setBlock(x+12,y+ 20,z+ 25, a)
    mc.setBlock(x+11,y+ 20,z+ 25, a)
    mc.setBlock(x+10,y+ 20,z+ 25, a)
    mc.setBlock(x+19,y+ 29,z+ 38, a)
    mc.setBlock(x+4,y+ 20,z+ 25, a)
    mc.setBlock(x+13,y+ 19,z+ 25, a)
    mc.setBlock(x+12,y+ 19,z+ 25, a)
    mc.setBlock(x+9,y+ 19,z+ 25, a)
    mc.setBlock(x+26,y+ 29,z+ 38, a)
    mc.setBlock(x+27,y+ 29,z+ 38, a)
    mc.setBlock(x+28,y+ 29,z+ 38, a)
    mc.setBlock(x+29,y+ 29,z+ 38, a)
    mc.setBlock(x+4,y+ 19,z+ 25, a)
    mc.setBlock(x+8,y+ 18,z+ 25, a)
    mc.setBlock(x+7,y+ 18,z+ 25, a)
    mc.setBlock(x+6,y+ 18,z+ 25, a)
    mc.setBlock(x+5,y+ 18,z+ 25, a)
    mc.setBlock(x+5,y+ 17,z+ 25, a)
    mc.setBlock(x+5,y+ 16,z+ 25, a)
    mc.setBlock(x+39,y+ 48,z+ 24, a)
    mc.setBlock(x+38,y+ 48,z+ 24, a)
    mc.setBlock(x+37,y+ 48,z+ 24, a)
    mc.setBlock(x+36,y+ 48,z+ 24, a)
    mc.setBlock(x+40,y+ 47,z+ 24, a)
    mc.setBlock(x+39,y+ 47,z+ 24, a)
    mc.setBlock(x+31,y+ 17,z+ 39, a)
    mc.setBlock(x+28,y+ 18,z+ 39, a)
    mc.setBlock(x+36,y+ 47,z+ 24, a)
    mc.setBlock(x+41,y+ 46,z+ 24, a)
    mc.setBlock(x+29,y+ 18,z+ 39, a)
    mc.setBlock(x+30,y+ 18,z+ 39, a)
    mc.setBlock(x+31,y+ 18,z+ 39, a)
    mc.setBlock(x+36,y+ 46,z+ 24, a)
    mc.setBlock(x+41,y+ 45,z+ 24, a)
    mc.setBlock(x+25,y+ 19,z+ 39, a)
    mc.setBlock(x+36,y+ 45,z+ 24, a)
    mc.setBlock(x+42,y+ 44,z+ 24, a)
    mc.setBlock(x+26,y+ 19,z+ 39, a)
    mc.setBlock(x+36,y+ 44,z+ 24, a)
    mc.setBlock(x+42,y+ 43,z+ 24, a)
    mc.setBlock(x+27,y+ 19,z+ 39, a)
    mc.setBlock(x+36,y+ 43,z+ 24, a)
    mc.setBlock(x+42,y+ 42,z+ 24, a)
    mc.setBlock(x+28,y+ 19,z+ 39, a)
    mc.setBlock(x+36,y+ 42,z+ 24, a)
    mc.setBlock(x+42,y+ 41,z+ 24, a)
    mc.setBlock(x+37,y+ 41,z+ 24, a)
    mc.setBlock(x+42,y+ 40,z+ 24, a)
    mc.setBlock(x+37,y+ 40,z+ 24, a)
    mc.setBlock(x+42,y+ 39,z+ 24, a)
    mc.setBlock(x+29,y+ 19,z+ 39, a)
    mc.setBlock(x+24,y+ 20,z+ 39, a)
    mc.setBlock(x+36,y+ 39,z+ 24, a)
    mc.setBlock(x+43,y+ 38,z+ 24, a)
    mc.setBlock(x+25,y+ 20,z+ 39, a)
    mc.setBlock(x+26,y+ 20,z+ 39, a)
    mc.setBlock(x+36,y+ 38,z+ 24, a)
    mc.setBlock(x+43,y+ 37,z+ 24, a)
    mc.setBlock(x+27,y+ 20,z+ 39, a)
    mc.setBlock(x+28,y+ 20,z+ 39, a)
    mc.setBlock(x+36,y+ 37,z+ 24, a)
    mc.setBlock(x+44,y+ 36,z+ 24, a)
    mc.setBlock(x+43,y+ 36,z+ 24, a)
    mc.setBlock(x+24,y+ 21,z+ 39, a)
    mc.setBlock(x+25,y+ 21,z+ 39, a)
    mc.setBlock(x+37,y+ 36,z+ 24, a)
    mc.setBlock(x+44,y+ 35,z+ 24, a)
    mc.setBlock(x+43,y+ 35,z+ 24, a)
    mc.setBlock(x+26,y+ 21,z+ 39, a)
    mc.setBlock(x+24,y+ 22,z+ 39, a)
    mc.setBlock(x+25,y+ 22,z+ 39, a)
    mc.setBlock(x+13,y+ 24,z+ 39, a)
    mc.setBlock(x+37,y+ 35,z+ 24, a)
    mc.setBlock(x+44,y+ 34,z+ 24, a)
    mc.setBlock(x+43,y+ 34,z+ 24, a)
    mc.setBlock(x+42,y+ 34,z+ 24, a)
    mc.setBlock(x+14,y+ 24,z+ 39, a)
    mc.setBlock(x+15,y+ 24,z+ 39, a)
    mc.setBlock(x+39,y+ 34,z+ 24, a)
    mc.setBlock(x+38,y+ 34,z+ 24, a)
    mc.setBlock(x+37,y+ 34,z+ 24, a)
    mc.setBlock(x+42,y+ 33,z+ 24, a)
    mc.setBlock(x+41,y+ 33,z+ 24, a)
    mc.setBlock(x+40,y+ 33,z+ 24, a)
    mc.setBlock(x+39,y+ 33,z+ 24, a)
    mc.setBlock(x+38,y+ 33,z+ 24, a)
    mc.setBlock(x+42,y+ 32,z+ 24, a)
    mc.setBlock(x+41,y+ 32,z+ 24, a)
    mc.setBlock(x+40,y+ 32,z+ 24, a)
    mc.setBlock(x+39,y+ 32,z+ 24, a)
    mc.setBlock(x+38,y+ 32,z+ 24, a)
    mc.setBlock(x+48,y+ 31,z+ 24, a)
    mc.setBlock(x+47,y+ 31,z+ 24, a)
    mc.setBlock(x+42,y+ 31,z+ 24, a)
    mc.setBlock(x+41,y+ 31,z+ 24, a)
    mc.setBlock(x+40,y+ 31,z+ 24, a)
    mc.setBlock(x+39,y+ 31,z+ 24, a)
    mc.setBlock(x+38,y+ 31,z+ 24, a)
    mc.setBlock(x+37,y+ 31,z+ 24, a)
    mc.setBlock(x+28,y+ 31,z+ 24, a)
    mc.setBlock(x+27,y+ 31,z+ 24, a)
    mc.setBlock(x+26,y+ 31,z+ 24, a)
    mc.setBlock(x+25,y+ 31,z+ 24, a)
    mc.setBlock(x+49,y+ 30,z+ 24, a)
    mc.setBlock(x+16,y+ 24,z+ 39, a)
    mc.setBlock(x+47,y+ 30,z+ 24, a)
    mc.setBlock(x+42,y+ 30,z+ 24, a)
    mc.setBlock(x+41,y+ 30,z+ 24, a)
    mc.setBlock(x+17,y+ 24,z+ 39, a)
    mc.setBlock(x+18,y+ 24,z+ 39, a)
    mc.setBlock(x+38,y+ 30,z+ 24, a)
    mc.setBlock(x+37,y+ 30,z+ 24, a)
    mc.setBlock(x+30,y+ 30,z+ 24, a)
    mc.setBlock(x+29,y+ 30,z+ 24, a)
    mc.setBlock(x+19,y+ 24,z+ 39, a)
    mc.setBlock(x+20,y+ 24,z+ 39, a)
    mc.setBlock(x+12,y+ 25,z+ 39, a)
    mc.setBlock(x+21,y+ 25,z+ 39, a)
    mc.setBlock(x+24,y+ 30,z+ 24, a)
    mc.setBlock(x+49,y+ 29,z+ 24, a)
    mc.setBlock(x+48,y+ 29,z+ 24, a)
    mc.setBlock(x+47,y+ 29,z+ 24, a)
    mc.setBlock(x+42,y+ 29,z+ 24, a)
    mc.setBlock(x+22,y+ 25,z+ 39, a)
    mc.setBlock(x+23,y+ 25,z+ 39, a)
    mc.setBlock(x+24,y+ 25,z+ 39, a)
    mc.setBlock(x+25,y+ 25,z+ 39, a)
    mc.setBlock(x+26,y+ 25,z+ 39, a)
    mc.setBlock(x+36,y+ 29,z+ 24, a)
    mc.setBlock(x+30,y+ 29,z+ 24, a)
    mc.setBlock(x+34,y+ 25,z+ 39, a)
    mc.setBlock(x+11,y+ 26,z+ 39, a)
    mc.setBlock(x+22,y+ 26,z+ 39, a)
    mc.setBlock(x+24,y+ 29,z+ 24, a)
    mc.setBlock(x+23,y+ 29,z+ 24, a)
    mc.setBlock(x+10,y+ 29,z+ 24, a)
    mc.setBlock(x+9,y+ 29,z+ 24, a)
    mc.setBlock(x+42,y+ 28,z+ 24, a)
    mc.setBlock(x+23,y+ 26,z+ 39, a)
    mc.setBlock(x+36,y+ 28,z+ 24, a)
    mc.setBlock(x+29,y+ 28,z+ 24, a)
    mc.setBlock(x+28,y+ 28,z+ 24, a)
    mc.setBlock(x+27,y+ 28,z+ 24, a)
    mc.setBlock(x+26,y+ 28,z+ 24, a)
    mc.setBlock(x+25,y+ 28,z+ 24, a)
    mc.setBlock(x+24,y+ 28,z+ 24, a)
    mc.setBlock(x+9,y+ 28,z+ 24, a)
    mc.setBlock(x+42,y+ 27,z+ 24, a)
    mc.setBlock(x+24,y+ 26,z+ 39, a)
    mc.setBlock(x+25,y+ 26,z+ 39, a)
    mc.setBlock(x+36,y+ 27,z+ 24, a)
    mc.setBlock(x+9,y+ 27,z+ 24, a)
    mc.setBlock(x+8,y+ 27,z+ 24, a)
    mc.setBlock(x+41,y+ 26,z+ 24, a)
    mc.setBlock(x+26,y+ 26,z+ 39, a)
    mc.setBlock(x+30,y+ 26,z+ 39, a)
    mc.setBlock(x+35,y+ 26,z+ 24, a)
    mc.setBlock(x+8,y+ 26,z+ 24, a)
    mc.setBlock(x+41,y+ 25,z+ 24, a)
    mc.setBlock(x+31,y+ 26,z+ 39, a)
    mc.setBlock(x+35,y+ 25,z+ 24, a)
    mc.setBlock(x+9,y+ 25,z+ 24, a)
    mc.setBlock(x+32,y+ 26,z+ 39, a)
    mc.setBlock(x+7,y+ 25,z+ 24, a)
    mc.setBlock(x+6,y+ 25,z+ 24, a)
    mc.setBlock(x+5,y+ 25,z+ 24, a)
    mc.setBlock(x+40,y+ 24,z+ 24, a)
    mc.setBlock(x+33,y+ 26,z+ 39, a)
    mc.setBlock(x+34,y+ 24,z+ 24, a)
    mc.setBlock(x+9,y+ 24,z+ 24, a)
    mc.setBlock(x+34,y+ 26,z+ 39, a)
    mc.setBlock(x+11,y+ 27,z+ 39, a)
    mc.setBlock(x+22,y+ 27,z+ 39, a)
    mc.setBlock(x+4,y+ 24,z+ 24, a)
    mc.setBlock(x+1,y+ 24,z+ 24, a)
    mc.setBlock(x+0,y+ 24,z+ 24, a)
    mc.setBlock(x+40,y+ 23,z+ 24, a)
    mc.setBlock(x+23,y+ 27,z+ 39, a)
    mc.setBlock(x+34,y+ 23,z+ 24, a)
    mc.setBlock(x+10,y+ 23,z+ 24, a)
    mc.setBlock(x+27,y+ 27,z+ 39, a)
    mc.setBlock(x+28,y+ 27,z+ 39, a)
    mc.setBlock(x+3,y+ 23,z+ 24, a)
    mc.setBlock(x+2,y+ 23,z+ 24, a)
    mc.setBlock(x+1,y+ 23,z+ 24, a)
    mc.setBlock(x+0,y+ 23,z+ 24, a)
    mc.setBlock(x+39,y+ 22,z+ 24, a)
    mc.setBlock(x+29,y+ 27,z+ 39, a)
    mc.setBlock(x+34,y+ 22,z+ 24, a)
    mc.setBlock(x+10,y+ 22,z+ 24, a)
    mc.setBlock(x+30,y+ 27,z+ 39, a)
    mc.setBlock(x+31,y+ 27,z+ 39, a)
    mc.setBlock(x+32,y+ 27,z+ 39, a)
    mc.setBlock(x+2,y+ 22,z+ 24, a)
    mc.setBlock(x+39,y+ 21,z+ 24, a)
    mc.setBlock(x+33,y+ 27,z+ 39, a)
    mc.setBlock(x+12,y+ 28,z+ 39, a)
    mc.setBlock(x+21,y+ 28,z+ 39, a)
    mc.setBlock(x+22,y+ 28,z+ 39, a)
    mc.setBlock(x+34,y+ 21,z+ 24, a)
    mc.setBlock(x+10,y+ 21,z+ 24, a)
    mc.setBlock(x+3,y+ 21,z+ 24, a)
    mc.setBlock(x+38,y+ 20,z+ 24, a)
    mc.setBlock(x+37,y+ 20,z+ 24, a)
    mc.setBlock(x+36,y+ 20,z+ 24, a)
    mc.setBlock(x+35,y+ 20,z+ 24, a)
    mc.setBlock(x+34,y+ 20,z+ 24, a)
    mc.setBlock(x+12,y+ 20,z+ 24, a)
    mc.setBlock(x+11,y+ 20,z+ 24, a)
    mc.setBlock(x+10,y+ 20,z+ 24, a)
    mc.setBlock(x+23,y+ 28,z+ 39, a)
    mc.setBlock(x+25,y+ 28,z+ 39, a)
    mc.setBlock(x+3,y+ 20,z+ 24, a)
    mc.setBlock(x+13,y+ 19,z+ 24, a)
    mc.setBlock(x+12,y+ 19,z+ 24, a)
    mc.setBlock(x+11,y+ 19,z+ 24, a)
    mc.setBlock(x+9,y+ 19,z+ 24, a)
    mc.setBlock(x+26,y+ 28,z+ 39, a)
    mc.setBlock(x+27,y+ 28,z+ 39, a)
    mc.setBlock(x+4,y+ 19,z+ 24, a)
    mc.setBlock(x+9,y+ 18,z+ 24, a)
    mc.setBlock(x+8,y+ 18,z+ 24, a)
    mc.setBlock(x+7,y+ 18,z+ 24, a)
    mc.setBlock(x+28,y+ 28,z+ 39, a)
    mc.setBlock(x+29,y+ 28,z+ 39, a)
    mc.setBlock(x+4,y+ 18,z+ 24, a)
    mc.setBlock(x+6,y+ 17,z+ 24, a)
    mc.setBlock(x+5,y+ 17,z+ 24, a)
    mc.setBlock(x+38,y+ 49,z+ 23, a)
    mc.setBlock(x+37,y+ 49,z+ 23, a)
    mc.setBlock(x+36,y+ 49,z+ 23, a)
    mc.setBlock(x+39,y+ 48,z+ 23, a)
    mc.setBlock(x+12,y+ 29,z+ 39, a)
    mc.setBlock(x+13,y+ 29,z+ 39, a)
    mc.setBlock(x+14,y+ 29,z+ 39, a)
    mc.setBlock(x+35,y+ 48,z+ 23, a)
    mc.setBlock(x+40,y+ 47,z+ 23, a)
    mc.setBlock(x+15,y+ 29,z+ 39, a)
    mc.setBlock(x+16,y+ 29,z+ 39, a)
    mc.setBlock(x+35,y+ 47,z+ 23, a)
    mc.setBlock(x+41,y+ 46,z+ 23, a)
    mc.setBlock(x+17,y+ 29,z+ 39, a)
    mc.setBlock(x+35,y+ 46,z+ 23, a)
    mc.setBlock(x+41,y+ 45,z+ 23, a)
    mc.setBlock(x+18,y+ 29,z+ 39, a)
    mc.setBlock(x+35,y+ 45,z+ 23, a)
    mc.setBlock(x+41,y+ 44,z+ 23, a)
    mc.setBlock(x+19,y+ 29,z+ 39, a)
    mc.setBlock(x+35,y+ 44,z+ 23, a)
    mc.setBlock(x+42,y+ 43,z+ 23, a)
    mc.setBlock(x+20,y+ 29,z+ 39, a)
    mc.setBlock(x+36,y+ 43,z+ 23, a)
    mc.setBlock(x+42,y+ 42,z+ 23, a)
    mc.setBlock(x+21,y+ 29,z+ 39, a)
    mc.setBlock(x+51,y+ 0,z+ 40, a)
    mc.setBlock(x+36,y+ 42,z+ 23, a)
    mc.setBlock(x+42,y+ 41,z+ 23, a)
    mc.setBlock(x+52,y+ 0,z+ 40, a)
    mc.setBlock(x+37,y+ 41,z+ 23, a)
    mc.setBlock(x+42,y+ 40,z+ 23, a)
    mc.setBlock(x+50,y+ 1,z+ 40, a)
    mc.setBlock(x+51,y+ 1,z+ 40, a)
    mc.setBlock(x+37,y+ 40,z+ 23, a)
    mc.setBlock(x+42,y+ 39,z+ 23, a)
    mc.setBlock(x+52,y+ 1,z+ 40, a)
    mc.setBlock(x+50,y+ 2,z+ 40, a)
    mc.setBlock(x+51,y+ 2,z+ 40, a)
    mc.setBlock(x+38,y+ 39,z+ 23, a)
    mc.setBlock(x+37,y+ 39,z+ 23, a)
    mc.setBlock(x+42,y+ 38,z+ 23, a)
    mc.setBlock(x+52,y+ 2,z+ 40, a)
    mc.setBlock(x+49,y+ 3,z+ 40, a)
    mc.setBlock(x+37,y+ 38,z+ 23, a)
    mc.setBlock(x+42,y+ 37,z+ 23, a)
    mc.setBlock(x+50,y+ 3,z+ 40, a)
    mc.setBlock(x+51,y+ 3,z+ 40, a)
    mc.setBlock(x+52,y+ 3,z+ 40, a)
    mc.setBlock(x+37,y+ 37,z+ 23, a)
    mc.setBlock(x+42,y+ 36,z+ 23, a)
    mc.setBlock(x+41,y+ 36,z+ 23, a)
    mc.setBlock(x+53,y+ 3,z+ 40, a)
    mc.setBlock(x+56,y+ 3,z+ 40, a)
    mc.setBlock(x+38,y+ 36,z+ 23, a)
    mc.setBlock(x+37,y+ 36,z+ 23, a)
    mc.setBlock(x+42,y+ 35,z+ 23, a)
    mc.setBlock(x+41,y+ 35,z+ 23, a)
    mc.setBlock(x+40,y+ 35,z+ 23, a)
    mc.setBlock(x+39,y+ 35,z+ 23, a)
    mc.setBlock(x+38,y+ 35,z+ 23, a)
    mc.setBlock(x+41,y+ 34,z+ 23, a)
    mc.setBlock(x+40,y+ 34,z+ 23, a)
    mc.setBlock(x+28,y+ 31,z+ 23, a)
    mc.setBlock(x+27,y+ 31,z+ 23, a)
    mc.setBlock(x+26,y+ 31,z+ 23, a)
    mc.setBlock(x+25,y+ 31,z+ 23, a)
    mc.setBlock(x+49,y+ 30,z+ 23, a)
    mc.setBlock(x+48,y+ 30,z+ 23, a)
    mc.setBlock(x+47,y+ 30,z+ 23, a)
    mc.setBlock(x+40,y+ 30,z+ 23, a)
    mc.setBlock(x+39,y+ 30,z+ 23, a)
    mc.setBlock(x+29,y+ 30,z+ 23, a)
    mc.setBlock(x+57,y+ 3,z+ 40, a)
    mc.setBlock(x+55,y+ 4,z+ 40, a)
    mc.setBlock(x+24,y+ 30,z+ 23, a)
    mc.setBlock(x+23,y+ 30,z+ 23, a)
    mc.setBlock(x+49,y+ 29,z+ 23, a)
    mc.setBlock(x+56,y+ 4,z+ 40, a)
    mc.setBlock(x+47,y+ 29,z+ 23, a)
    mc.setBlock(x+41,y+ 29,z+ 23, a)
    mc.setBlock(x+40,y+ 29,z+ 23, a)
    mc.setBlock(x+39,y+ 29,z+ 23, a)
    mc.setBlock(x+38,y+ 29,z+ 23, a)
    mc.setBlock(x+37,y+ 29,z+ 23, a)
    mc.setBlock(x+29,y+ 29,z+ 23, a)
    mc.setBlock(x+29,y+ 18,z+ 40, a)
    mc.setBlock(x+30,y+ 18,z+ 40, a)
    mc.setBlock(x+31,y+ 18,z+ 40, a)
    mc.setBlock(x+32,y+ 18,z+ 40, a)
    mc.setBlock(x+22,y+ 29,z+ 23, a)
    mc.setBlock(x+9,y+ 29,z+ 23, a)
    mc.setBlock(x+49,y+ 28,z+ 23, a)
    mc.setBlock(x+48,y+ 28,z+ 23, a)
    mc.setBlock(x+47,y+ 28,z+ 23, a)
    mc.setBlock(x+41,y+ 28,z+ 23, a)
    mc.setBlock(x+40,y+ 28,z+ 23, a)
    mc.setBlock(x+28,y+ 19,z+ 40, a)
    mc.setBlock(x+29,y+ 19,z+ 40, a)
    mc.setBlock(x+37,y+ 28,z+ 23, a)
    mc.setBlock(x+36,y+ 28,z+ 23, a)
    mc.setBlock(x+29,y+ 28,z+ 23, a)
    mc.setBlock(x+28,y+ 28,z+ 23, a)
    mc.setBlock(x+27,y+ 28,z+ 23, a)
    mc.setBlock(x+26,y+ 28,z+ 23, a)
    mc.setBlock(x+25,y+ 28,z+ 23, a)
    mc.setBlock(x+24,y+ 28,z+ 23, a)
    mc.setBlock(x+23,y+ 28,z+ 23, a)
    mc.setBlock(x+9,y+ 28,z+ 23, a)
    mc.setBlock(x+41,y+ 27,z+ 23, a)
    mc.setBlock(x+40,y+ 27,z+ 23, a)
    mc.setBlock(x+30,y+ 19,z+ 40, a)
    mc.setBlock(x+31,y+ 19,z+ 40, a)
    mc.setBlock(x+37,y+ 27,z+ 23, a)
    mc.setBlock(x+36,y+ 27,z+ 23, a)
    mc.setBlock(x+9,y+ 27,z+ 23, a)
    mc.setBlock(x+8,y+ 27,z+ 23, a)
    mc.setBlock(x+41,y+ 26,z+ 23, a)
    mc.setBlock(x+40,y+ 26,z+ 23, a)
    mc.setBlock(x+32,y+ 19,z+ 40, a)
    mc.setBlock(x+26,y+ 20,z+ 40, a)
    mc.setBlock(x+27,y+ 20,z+ 40, a)
    mc.setBlock(x+35,y+ 26,z+ 23, a)
    mc.setBlock(x+8,y+ 26,z+ 23, a)
    mc.setBlock(x+40,y+ 25,z+ 23, a)
    mc.setBlock(x+28,y+ 20,z+ 40, a)
    mc.setBlock(x+29,y+ 20,z+ 40, a)
    mc.setBlock(x+35,y+ 25,z+ 23, a)
    mc.setBlock(x+8,y+ 25,z+ 23, a)
    mc.setBlock(x+7,y+ 25,z+ 23, a)
    mc.setBlock(x+6,y+ 25,z+ 23, a)
    mc.setBlock(x+40,y+ 24,z+ 23, a)
    mc.setBlock(x+30,y+ 20,z+ 40, a)
    mc.setBlock(x+34,y+ 24,z+ 23, a)
    mc.setBlock(x+9,y+ 24,z+ 23, a)
    mc.setBlock(x+24,y+ 21,z+ 40, a)
    mc.setBlock(x+25,y+ 21,z+ 40, a)
    mc.setBlock(x+26,y+ 21,z+ 40, a)
    mc.setBlock(x+5,y+ 24,z+ 23, a)
    mc.setBlock(x+4,y+ 24,z+ 23, a)
    mc.setBlock(x+40,y+ 23,z+ 23, a)
    mc.setBlock(x+27,y+ 21,z+ 40, a)
    mc.setBlock(x+34,y+ 23,z+ 23, a)
    mc.setBlock(x+9,y+ 23,z+ 23, a)
    mc.setBlock(x+4,y+ 23,z+ 23, a)
    mc.setBlock(x+2,y+ 23,z+ 23, a)
    mc.setBlock(x+1,y+ 23,z+ 23, a)
    mc.setBlock(x+0,y+ 23,z+ 23, a)
    mc.setBlock(x+39,y+ 22,z+ 23, a)
    mc.setBlock(x+28,y+ 21,z+ 40, a)
    mc.setBlock(x+33,y+ 22,z+ 23, a)
    mc.setBlock(x+10,y+ 22,z+ 23, a)
    mc.setBlock(x+24,y+ 22,z+ 40, a)
    mc.setBlock(x+26,y+ 22,z+ 40, a)
    mc.setBlock(x+3,y+ 22,z+ 23, a)
    mc.setBlock(x+2,y+ 22,z+ 23, a)
    mc.setBlock(x+1,y+ 22,z+ 23, a)
    mc.setBlock(x+39,y+ 21,z+ 23, a)
    mc.setBlock(x+28,y+ 22,z+ 40, a)
    mc.setBlock(x+29,y+ 22,z+ 40, a)
    mc.setBlock(x+33,y+ 21,z+ 23, a)
    mc.setBlock(x+10,y+ 21,z+ 23, a)
    mc.setBlock(x+3,y+ 21,z+ 23, a)
    mc.setBlock(x+38,y+ 20,z+ 23, a)
    mc.setBlock(x+30,y+ 22,z+ 40, a)
    mc.setBlock(x+31,y+ 22,z+ 40, a)
    mc.setBlock(x+32,y+ 22,z+ 40, a)
    mc.setBlock(x+24,y+ 23,z+ 40, a)
    mc.setBlock(x+33,y+ 20,z+ 23, a)
    mc.setBlock(x+11,y+ 20,z+ 23, a)
    mc.setBlock(x+25,y+ 23,z+ 40, a)
    mc.setBlock(x+26,y+ 23,z+ 40, a)
    mc.setBlock(x+27,y+ 23,z+ 40, a)
    mc.setBlock(x+3,y+ 20,z+ 23, a)
    mc.setBlock(x+37,y+ 19,z+ 23, a)
    mc.setBlock(x+36,y+ 19,z+ 23, a)
    mc.setBlock(x+35,y+ 19,z+ 23, a)
    mc.setBlock(x+34,y+ 19,z+ 23, a)
    mc.setBlock(x+13,y+ 19,z+ 23, a)
    mc.setBlock(x+12,y+ 19,z+ 23, a)
    mc.setBlock(x+11,y+ 19,z+ 23, a)
    mc.setBlock(x+10,y+ 19,z+ 23, a)
    mc.setBlock(x+28,y+ 23,z+ 40, a)
    mc.setBlock(x+4,y+ 19,z+ 23, a)
    mc.setBlock(x+13,y+ 18,z+ 23, a)
    mc.setBlock(x+12,y+ 18,z+ 23, a)
    mc.setBlock(x+9,y+ 18,z+ 23, a)
    mc.setBlock(x+8,y+ 18,z+ 23, a)
    mc.setBlock(x+29,y+ 23,z+ 40, a)
    mc.setBlock(x+30,y+ 23,z+ 40, a)
    mc.setBlock(x+31,y+ 23,z+ 40, a)
    mc.setBlock(x+4,y+ 18,z+ 23, a)
    mc.setBlock(x+7,y+ 17,z+ 23, a)
    mc.setBlock(x+6,y+ 17,z+ 23, a)
    mc.setBlock(x+5,y+ 17,z+ 23, a)
    mc.setBlock(x+37,y+ 50,z+ 22, a)
    mc.setBlock(x+36,y+ 50,z+ 22, a)
    mc.setBlock(x+35,y+ 50,z+ 22, a)
    mc.setBlock(x+39,y+ 49,z+ 22, a)
    mc.setBlock(x+38,y+ 49,z+ 22, a)
    mc.setBlock(x+32,y+ 23,z+ 40, a)
    mc.setBlock(x+33,y+ 23,z+ 40, a)
    mc.setBlock(x+35,y+ 49,z+ 22, a)
    mc.setBlock(x+34,y+ 49,z+ 22, a)
    mc.setBlock(x+40,y+ 48,z+ 22, a)
    mc.setBlock(x+15,y+ 24,z+ 40, a)
    mc.setBlock(x+16,y+ 24,z+ 40, a)
    mc.setBlock(x+34,y+ 48,z+ 22, a)
    mc.setBlock(x+40,y+ 47,z+ 22, a)
    mc.setBlock(x+17,y+ 24,z+ 40, a)
    mc.setBlock(x+34,y+ 47,z+ 22, a)
    mc.setBlock(x+41,y+ 46,z+ 22, a)
    mc.setBlock(x+18,y+ 24,z+ 40, a)
    mc.setBlock(x+19,y+ 24,z+ 40, a)
    mc.setBlock(x+34,y+ 46,z+ 22, a)
    mc.setBlock(x+41,y+ 45,z+ 22, a)
    mc.setBlock(x+35,y+ 45,z+ 22, a)
    mc.setBlock(x+41,y+ 44,z+ 22, a)
    mc.setBlock(x+20,y+ 24,z+ 40, a)
    mc.setBlock(x+35,y+ 44,z+ 22, a)
    mc.setBlock(x+41,y+ 43,z+ 22, a)
    mc.setBlock(x+21,y+ 24,z+ 40, a)
    mc.setBlock(x+36,y+ 43,z+ 22, a)
    mc.setBlock(x+41,y+ 42,z+ 22, a)
    mc.setBlock(x+22,y+ 24,z+ 40, a)
    mc.setBlock(x+23,y+ 24,z+ 40, a)
    mc.setBlock(x+37,y+ 42,z+ 22, a)
    mc.setBlock(x+41,y+ 41,z+ 22, a)
    mc.setBlock(x+24,y+ 24,z+ 40, a)
    mc.setBlock(x+25,y+ 24,z+ 40, a)
    mc.setBlock(x+38,y+ 41,z+ 22, a)
    mc.setBlock(x+37,y+ 41,z+ 22, a)
    mc.setBlock(x+41,y+ 40,z+ 22, a)
    mc.setBlock(x+40,y+ 40,z+ 22, a)
    mc.setBlock(x+39,y+ 40,z+ 22, a)
    mc.setBlock(x+38,y+ 40,z+ 22, a)
    mc.setBlock(x+41,y+ 39,z+ 22, a)
    mc.setBlock(x+40,y+ 39,z+ 22, a)
    mc.setBlock(x+39,y+ 39,z+ 22, a)
    mc.setBlock(x+41,y+ 38,z+ 22, a)
    mc.setBlock(x+40,y+ 38,z+ 22, a)
    mc.setBlock(x+39,y+ 38,z+ 22, a)
    mc.setBlock(x+38,y+ 38,z+ 22, a)
    mc.setBlock(x+41,y+ 37,z+ 22, a)
    mc.setBlock(x+40,y+ 37,z+ 22, a)
    mc.setBlock(x+39,y+ 37,z+ 22, a)
    mc.setBlock(x+38,y+ 37,z+ 22, a)
    mc.setBlock(x+40,y+ 36,z+ 22, a)
    mc.setBlock(x+39,y+ 36,z+ 22, a)
    mc.setBlock(x+25,y+ 33,z+ 22, a)
    mc.setBlock(x+26,y+ 32,z+ 22, a)
    mc.setBlock(x+25,y+ 32,z+ 22, a)
    mc.setBlock(x+24,y+ 32,z+ 22, a)
    mc.setBlock(x+29,y+ 31,z+ 22, a)
    mc.setBlock(x+28,y+ 31,z+ 22, a)
    mc.setBlock(x+27,y+ 31,z+ 22, a)
    mc.setBlock(x+26,y+ 24,z+ 40, a)
    mc.setBlock(x+27,y+ 24,z+ 40, a)
    mc.setBlock(x+24,y+ 31,z+ 22, a)
    mc.setBlock(x+49,y+ 30,z+ 22, a)
    mc.setBlock(x+48,y+ 30,z+ 22, a)
    mc.setBlock(x+47,y+ 30,z+ 22, a)
    mc.setBlock(x+29,y+ 30,z+ 22, a)
    mc.setBlock(x+28,y+ 24,z+ 40, a)
    mc.setBlock(x+29,y+ 24,z+ 40, a)
    mc.setBlock(x+24,y+ 30,z+ 22, a)
    mc.setBlock(x+23,y+ 30,z+ 22, a)
    mc.setBlock(x+49,y+ 29,z+ 22, a)
    mc.setBlock(x+47,y+ 29,z+ 22, a)
    mc.setBlock(x+29,y+ 29,z+ 22, a)
    mc.setBlock(x+30,y+ 24,z+ 40, a)
    mc.setBlock(x+26,y+ 29,z+ 22, a)
    mc.setBlock(x+25,y+ 29,z+ 22, a)
    mc.setBlock(x+24,y+ 29,z+ 22, a)
    mc.setBlock(x+31,y+ 24,z+ 40, a)
    mc.setBlock(x+22,y+ 29,z+ 22, a)
    mc.setBlock(x+49,y+ 28,z+ 22, a)
    mc.setBlock(x+48,y+ 28,z+ 22, a)
    mc.setBlock(x+47,y+ 28,z+ 22, a)
    mc.setBlock(x+39,y+ 28,z+ 22, a)
    mc.setBlock(x+38,y+ 28,z+ 22, a)
    mc.setBlock(x+29,y+ 28,z+ 22, a)
    mc.setBlock(x+28,y+ 28,z+ 22, a)
    mc.setBlock(x+27,y+ 28,z+ 22, a)
    mc.setBlock(x+26,y+ 28,z+ 22, a)
    mc.setBlock(x+24,y+ 28,z+ 22, a)
    mc.setBlock(x+23,y+ 28,z+ 22, a)
    mc.setBlock(x+9,y+ 28,z+ 22, a)
    mc.setBlock(x+39,y+ 27,z+ 22, a)
    mc.setBlock(x+38,y+ 27,z+ 22, a)
    mc.setBlock(x+9,y+ 27,z+ 22, a)
    mc.setBlock(x+8,y+ 27,z+ 22, a)
    mc.setBlock(x+39,y+ 26,z+ 22, a)
    mc.setBlock(x+38,y+ 26,z+ 22, a)
    mc.setBlock(x+37,y+ 26,z+ 22, a)
    mc.setBlock(x+36,y+ 26,z+ 22, a)
    mc.setBlock(x+8,y+ 26,z+ 22, a)
    mc.setBlock(x+39,y+ 25,z+ 22, a)
    mc.setBlock(x+32,y+ 24,z+ 40, a)
    mc.setBlock(x+34,y+ 24,z+ 40, a)
    mc.setBlock(x+35,y+ 24,z+ 40, a)
    mc.setBlock(x+35,y+ 25,z+ 22, a)
    mc.setBlock(x+8,y+ 25,z+ 22, a)
    mc.setBlock(x+7,y+ 25,z+ 22, a)
    mc.setBlock(x+39,y+ 24,z+ 22, a)
    mc.setBlock(x+13,y+ 25,z+ 40, a)
    mc.setBlock(x+14,y+ 25,z+ 40, a)
    mc.setBlock(x+34,y+ 24,z+ 22, a)
    mc.setBlock(x+8,y+ 24,z+ 22, a)
    mc.setBlock(x+27,y+ 25,z+ 40, a)
    mc.setBlock(x+6,y+ 24,z+ 22, a)
    mc.setBlock(x+5,y+ 24,z+ 22, a)
    mc.setBlock(x+39,y+ 23,z+ 22, a)
    mc.setBlock(x+28,y+ 25,z+ 40, a)
    mc.setBlock(x+33,y+ 23,z+ 22, a)
    mc.setBlock(x+9,y+ 23,z+ 22, a)
    mc.setBlock(x+29,y+ 25,z+ 40, a)
    mc.setBlock(x+30,y+ 25,z+ 40, a)
    mc.setBlock(x+4,y+ 23,z+ 22, a)
    mc.setBlock(x+39,y+ 22,z+ 22, a)
    mc.setBlock(x+33,y+ 22,z+ 22, a)
    mc.setBlock(x+9,y+ 22,z+ 22, a)
    mc.setBlock(x+31,y+ 25,z+ 40, a)
    mc.setBlock(x+3,y+ 22,z+ 22, a)
    mc.setBlock(x+2,y+ 22,z+ 22, a)
    mc.setBlock(x+39,y+ 21,z+ 22, a)
    mc.setBlock(x+32,y+ 25,z+ 40, a)
    mc.setBlock(x+33,y+ 21,z+ 22, a)
    mc.setBlock(x+10,y+ 21,z+ 22, a)
    mc.setBlock(x+33,y+ 25,z+ 40, a)
    mc.setBlock(x+34,y+ 25,z+ 40, a)
    mc.setBlock(x+3,y+ 21,z+ 22, a)
    mc.setBlock(x+38,y+ 20,z+ 22, a)
    mc.setBlock(x+35,y+ 25,z+ 40, a)
    mc.setBlock(x+12,y+ 26,z+ 40, a)
    mc.setBlock(x+32,y+ 20,z+ 22, a)
    mc.setBlock(x+10,y+ 20,z+ 22, a)
    mc.setBlock(x+13,y+ 26,z+ 40, a)
    mc.setBlock(x+3,y+ 20,z+ 22, a)
    mc.setBlock(x+38,y+ 19,z+ 22, a)
    mc.setBlock(x+37,y+ 19,z+ 22, a)
    mc.setBlock(x+27,y+ 26,z+ 40, a)
    mc.setBlock(x+28,y+ 26,z+ 40, a)
    mc.setBlock(x+29,y+ 26,z+ 40, a)
    mc.setBlock(x+33,y+ 19,z+ 22, a)
    mc.setBlock(x+9,y+ 19,z+ 22, a)
    mc.setBlock(x+31,y+ 26,z+ 40, a)
    mc.setBlock(x+4,y+ 19,z+ 22, a)
    mc.setBlock(x+36,y+ 18,z+ 22, a)
    mc.setBlock(x+35,y+ 18,z+ 22, a)
    mc.setBlock(x+34,y+ 18,z+ 22, a)
    mc.setBlock(x+33,y+ 18,z+ 22, a)
    mc.setBlock(x+9,y+ 18,z+ 22, a)
    mc.setBlock(x+32,y+ 26,z+ 40, a)
    mc.setBlock(x+33,y+ 26,z+ 40, a)
    mc.setBlock(x+12,y+ 27,z+ 40, a)
    mc.setBlock(x+5,y+ 18,z+ 22, a)
    mc.setBlock(x+4,y+ 18,z+ 22, a)
    mc.setBlock(x+8,y+ 17,z+ 22, a)
    mc.setBlock(x+7,y+ 17,z+ 22, a)
    mc.setBlock(x+6,y+ 17,z+ 22, a)
    mc.setBlock(x+36,y+ 51,z+ 21, a)
    mc.setBlock(x+35,y+ 51,z+ 21, a)
    mc.setBlock(x+38,y+ 50,z+ 21, a)
    mc.setBlock(x+37,y+ 50,z+ 21, a)
    mc.setBlock(x+13,y+ 27,z+ 40, a)
    mc.setBlock(x+24,y+ 27,z+ 40, a)
    mc.setBlock(x+34,y+ 50,z+ 21, a)
    mc.setBlock(x+39,y+ 49,z+ 21, a)
    mc.setBlock(x+25,y+ 27,z+ 40, a)
    mc.setBlock(x+26,y+ 27,z+ 40, a)
    mc.setBlock(x+28,y+ 27,z+ 40, a)
    mc.setBlock(x+33,y+ 49,z+ 21, a)
    mc.setBlock(x+40,y+ 48,z+ 21, a)
    mc.setBlock(x+29,y+ 27,z+ 40, a)
    mc.setBlock(x+30,y+ 27,z+ 40, a)
    mc.setBlock(x+33,y+ 48,z+ 21, a)
    mc.setBlock(x+40,y+ 47,z+ 21, a)
    mc.setBlock(x+34,y+ 47,z+ 21, a)
    mc.setBlock(x+40,y+ 46,z+ 21, a)
    mc.setBlock(x+13,y+ 28,z+ 40, a)
    mc.setBlock(x+34,y+ 46,z+ 21, a)
    mc.setBlock(x+41,y+ 45,z+ 21, a)
    mc.setBlock(x+24,y+ 28,z+ 40, a)
    mc.setBlock(x+25,y+ 28,z+ 40, a)
    mc.setBlock(x+35,y+ 45,z+ 21, a)
    mc.setBlock(x+41,y+ 44,z+ 21, a)
    mc.setBlock(x+26,y+ 28,z+ 40, a)
    mc.setBlock(x+27,y+ 28,z+ 40, a)
    mc.setBlock(x+13,y+ 29,z+ 40, a)
    mc.setBlock(x+14,y+ 29,z+ 40, a)
    mc.setBlock(x+35,y+ 44,z+ 21, a)
    mc.setBlock(x+41,y+ 43,z+ 21, a)
    mc.setBlock(x+40,y+ 43,z+ 21, a)
    mc.setBlock(x+15,y+ 29,z+ 40, a)
    mc.setBlock(x+16,y+ 29,z+ 40, a)
    mc.setBlock(x+17,y+ 29,z+ 40, a)
    mc.setBlock(x+36,y+ 43,z+ 21, a)
    mc.setBlock(x+40,y+ 42,z+ 21, a)
    mc.setBlock(x+39,y+ 42,z+ 21, a)
    mc.setBlock(x+38,y+ 42,z+ 21, a)
    mc.setBlock(x+37,y+ 42,z+ 21, a)
    mc.setBlock(x+40,y+ 41,z+ 21, a)
    mc.setBlock(x+39,y+ 41,z+ 21, a)
    mc.setBlock(x+25,y+ 33,z+ 21, a)
    mc.setBlock(x+24,y+ 33,z+ 21, a)
    mc.setBlock(x+26,y+ 32,z+ 21, a)
    mc.setBlock(x+18,y+ 29,z+ 40, a)
    mc.setBlock(x+24,y+ 32,z+ 21, a)
    mc.setBlock(x+28,y+ 31,z+ 21, a)
    mc.setBlock(x+27,y+ 31,z+ 21, a)
    mc.setBlock(x+19,y+ 29,z+ 40, a)
    mc.setBlock(x+20,y+ 29,z+ 40, a)
    mc.setBlock(x+24,y+ 31,z+ 21, a)
    mc.setBlock(x+50,y+ 30,z+ 21, a)
    mc.setBlock(x+49,y+ 30,z+ 21, a)
    mc.setBlock(x+48,y+ 30,z+ 21, a)
    mc.setBlock(x+47,y+ 30,z+ 21, a)
    mc.setBlock(x+46,y+ 30,z+ 21, a)
    mc.setBlock(x+29,y+ 30,z+ 21, a)
    mc.setBlock(x+21,y+ 29,z+ 40, a)
    mc.setBlock(x+22,y+ 29,z+ 40, a)
    mc.setBlock(x+26,y+ 30,z+ 21, a)
    mc.setBlock(x+25,y+ 30,z+ 21, a)
    mc.setBlock(x+50,y+ 29,z+ 21, a)
    mc.setBlock(x+23,y+ 29,z+ 40, a)
    mc.setBlock(x+50,y+ 2,z+ 41, a)
    mc.setBlock(x+51,y+ 2,z+ 41, a)
    mc.setBlock(x+46,y+ 29,z+ 21, a)
    mc.setBlock(x+29,y+ 29,z+ 21, a)
    mc.setBlock(x+52,y+ 2,z+ 41, a)
    mc.setBlock(x+27,y+ 29,z+ 21, a)
    mc.setBlock(x+23,y+ 29,z+ 21, a)
    mc.setBlock(x+22,y+ 29,z+ 21, a)
    mc.setBlock(x+50,y+ 28,z+ 21, a)
    mc.setBlock(x+49,y+ 28,z+ 21, a)
    mc.setBlock(x+48,y+ 28,z+ 21, a)
    mc.setBlock(x+47,y+ 28,z+ 21, a)
    mc.setBlock(x+28,y+ 28,z+ 21, a)
    mc.setBlock(x+9,y+ 28,z+ 21, a)
    mc.setBlock(x+8,y+ 28,z+ 21, a)
    mc.setBlock(x+9,y+ 27,z+ 21, a)
    mc.setBlock(x+8,y+ 27,z+ 21, a)
    mc.setBlock(x+8,y+ 26,z+ 21, a)
    mc.setBlock(x+38,y+ 25,z+ 21, a)
    mc.setBlock(x+37,y+ 25,z+ 21, a)
    mc.setBlock(x+36,y+ 25,z+ 21, a)
    mc.setBlock(x+35,y+ 25,z+ 21, a)
    mc.setBlock(x+8,y+ 25,z+ 21, a)
    mc.setBlock(x+7,y+ 25,z+ 21, a)
    mc.setBlock(x+39,y+ 24,z+ 21, a)
    mc.setBlock(x+38,y+ 24,z+ 21, a)
    mc.setBlock(x+49,y+ 3,z+ 41, a)
    mc.setBlock(x+50,y+ 3,z+ 41, a)
    mc.setBlock(x+51,y+ 3,z+ 41, a)
    mc.setBlock(x+34,y+ 24,z+ 21, a)
    mc.setBlock(x+8,y+ 24,z+ 21, a)
    mc.setBlock(x+7,y+ 24,z+ 21, a)
    mc.setBlock(x+6,y+ 24,z+ 21, a)
    mc.setBlock(x+39,y+ 23,z+ 21, a)
    mc.setBlock(x+52,y+ 3,z+ 41, a)
    mc.setBlock(x+53,y+ 3,z+ 41, a)
    mc.setBlock(x+33,y+ 23,z+ 21, a)
    mc.setBlock(x+9,y+ 23,z+ 21, a)
    mc.setBlock(x+55,y+ 3,z+ 41, a)
    mc.setBlock(x+56,y+ 3,z+ 41, a)
    mc.setBlock(x+49,y+ 4,z+ 41, a)
    mc.setBlock(x+5,y+ 23,z+ 21, a)
    mc.setBlock(x+4,y+ 23,z+ 21, a)
    mc.setBlock(x+39,y+ 22,z+ 21, a)
    mc.setBlock(x+50,y+ 4,z+ 41, a)
    mc.setBlock(x+33,y+ 22,z+ 21, a)
    mc.setBlock(x+9,y+ 22,z+ 21, a)
    mc.setBlock(x+51,y+ 4,z+ 41, a)
    mc.setBlock(x+52,y+ 4,z+ 41, a)
    mc.setBlock(x+4,y+ 22,z+ 21, a)
    mc.setBlock(x+39,y+ 21,z+ 21, a)
    mc.setBlock(x+53,y+ 4,z+ 41, a)
    mc.setBlock(x+54,y+ 4,z+ 41, a)
    mc.setBlock(x+32,y+ 21,z+ 21, a)
    mc.setBlock(x+9,y+ 21,z+ 21, a)
    mc.setBlock(x+56,y+ 4,z+ 41, a)
    mc.setBlock(x+48,y+ 5,z+ 41, a)
    mc.setBlock(x+3,y+ 21,z+ 21, a)
    mc.setBlock(x+38,y+ 20,z+ 21, a)
    mc.setBlock(x+32,y+ 20,z+ 21, a)
    mc.setBlock(x+9,y+ 20,z+ 21, a)
    mc.setBlock(x+49,y+ 5,z+ 41, a)
    mc.setBlock(x+3,y+ 20,z+ 21, a)
    mc.setBlock(x+38,y+ 19,z+ 21, a)
    mc.setBlock(x+50,y+ 5,z+ 41, a)
    mc.setBlock(x+51,y+ 5,z+ 41, a)
    mc.setBlock(x+52,y+ 5,z+ 41, a)
    mc.setBlock(x+32,y+ 19,z+ 21, a)
    mc.setBlock(x+9,y+ 19,z+ 21, a)
    mc.setBlock(x+4,y+ 19,z+ 21, a)
    mc.setBlock(x+37,y+ 18,z+ 21, a)
    mc.setBlock(x+36,y+ 18,z+ 21, a)
    mc.setBlock(x+53,y+ 5,z+ 41, a)
    mc.setBlock(x+54,y+ 5,z+ 41, a)
    mc.setBlock(x+55,y+ 5,z+ 41, a)
    mc.setBlock(x+32,y+ 18,z+ 21, a)
    mc.setBlock(x+9,y+ 18,z+ 21, a)
    mc.setBlock(x+47,y+ 6,z+ 41, a)
    mc.setBlock(x+48,y+ 6,z+ 41, a)
    mc.setBlock(x+4,y+ 18,z+ 21, a)
    mc.setBlock(x+35,y+ 17,z+ 21, a)
    mc.setBlock(x+34,y+ 17,z+ 21, a)
    mc.setBlock(x+33,y+ 17,z+ 21, a)
    mc.setBlock(x+9,y+ 17,z+ 21, a)
    mc.setBlock(x+8,y+ 17,z+ 21, a)
    mc.setBlock(x+7,y+ 17,z+ 21, a)
    mc.setBlock(x+6,y+ 17,z+ 21, a)
    mc.setBlock(x+5,y+ 17,z+ 21, a)
    mc.setBlock(x+37,y+ 51,z+ 20, a)
    mc.setBlock(x+36,y+ 51,z+ 20, a)
    mc.setBlock(x+35,y+ 51,z+ 20, a)
    mc.setBlock(x+34,y+ 51,z+ 20, a)
    mc.setBlock(x+33,y+ 51,z+ 20, a)
    mc.setBlock(x+38,y+ 50,z+ 20, a)
    mc.setBlock(x+49,y+ 6,z+ 41, a)
    mc.setBlock(x+50,y+ 6,z+ 41, a)
    mc.setBlock(x+51,y+ 6,z+ 41, a)
    mc.setBlock(x+33,y+ 50,z+ 20, a)
    mc.setBlock(x+39,y+ 49,z+ 20, a)
    mc.setBlock(x+52,y+ 6,z+ 41, a)
    mc.setBlock(x+33,y+ 49,z+ 20, a)
    mc.setBlock(x+39,y+ 48,z+ 20, a)
    mc.setBlock(x+53,y+ 6,z+ 41, a)
    mc.setBlock(x+33,y+ 48,z+ 20, a)
    mc.setBlock(x+40,y+ 47,z+ 20, a)
    mc.setBlock(x+54,y+ 6,z+ 41, a)
    mc.setBlock(x+55,y+ 6,z+ 41, a)
    mc.setBlock(x+33,y+ 47,z+ 20, a)
    mc.setBlock(x+40,y+ 46,z+ 20, a)
    mc.setBlock(x+56,y+ 6,z+ 41, a)
    mc.setBlock(x+47,y+ 7,z+ 41, a)
    mc.setBlock(x+34,y+ 46,z+ 20, a)
    mc.setBlock(x+40,y+ 45,z+ 20, a)
    mc.setBlock(x+48,y+ 7,z+ 41, a)
    mc.setBlock(x+49,y+ 7,z+ 41, a)
    mc.setBlock(x+50,y+ 7,z+ 41, a)
    mc.setBlock(x+51,y+ 7,z+ 41, a)
    mc.setBlock(x+35,y+ 45,z+ 20, a)
    mc.setBlock(x+40,y+ 44,z+ 20, a)
    mc.setBlock(x+39,y+ 44,z+ 20, a)
    mc.setBlock(x+38,y+ 44,z+ 20, a)
    mc.setBlock(x+37,y+ 44,z+ 20, a)
    mc.setBlock(x+36,y+ 44,z+ 20, a)
    mc.setBlock(x+39,y+ 43,z+ 20, a)
    mc.setBlock(x+38,y+ 43,z+ 20, a)
    mc.setBlock(x+37,y+ 43,z+ 20, a)
    mc.setBlock(x+24,y+ 33,z+ 20, a)
    mc.setBlock(x+25,y+ 32,z+ 20, a)
    mc.setBlock(x+24,y+ 32,z+ 20, a)
    mc.setBlock(x+49,y+ 31,z+ 20, a)
    mc.setBlock(x+48,y+ 31,z+ 20, a)
    mc.setBlock(x+47,y+ 31,z+ 20, a)
    mc.setBlock(x+28,y+ 31,z+ 20, a)
    mc.setBlock(x+27,y+ 31,z+ 20, a)
    mc.setBlock(x+26,y+ 31,z+ 20, a)
    mc.setBlock(x+25,y+ 31,z+ 20, a)
    mc.setBlock(x+24,y+ 31,z+ 20, a)
    mc.setBlock(x+50,y+ 30,z+ 20, a)
    mc.setBlock(x+52,y+ 7,z+ 41, a)
    mc.setBlock(x+53,y+ 7,z+ 41, a)
    mc.setBlock(x+55,y+ 7,z+ 41, a)
    mc.setBlock(x+46,y+ 30,z+ 20, a)
    mc.setBlock(x+28,y+ 30,z+ 20, a)
    mc.setBlock(x+56,y+ 7,z+ 41, a)
    mc.setBlock(x+26,y+ 30,z+ 20, a)
    mc.setBlock(x+51,y+ 29,z+ 20, a)
    mc.setBlock(x+57,y+ 7,z+ 41, a)
    mc.setBlock(x+49,y+ 8,z+ 41, a)
    mc.setBlock(x+46,y+ 29,z+ 20, a)
    mc.setBlock(x+28,y+ 29,z+ 20, a)
    mc.setBlock(x+27,y+ 29,z+ 20, a)
    mc.setBlock(x+51,y+ 28,z+ 20, a)
    mc.setBlock(x+50,y+ 8,z+ 41, a)
    mc.setBlock(x+51,y+ 8,z+ 41, a)
    mc.setBlock(x+52,y+ 8,z+ 41, a)
    mc.setBlock(x+47,y+ 28,z+ 20, a)
    mc.setBlock(x+46,y+ 28,z+ 20, a)
    mc.setBlock(x+50,y+ 27,z+ 20, a)
    mc.setBlock(x+49,y+ 27,z+ 20, a)
    mc.setBlock(x+48,y+ 27,z+ 20, a)
    mc.setBlock(x+9,y+ 27,z+ 20, a)
    mc.setBlock(x+8,y+ 27,z+ 20, a)
    mc.setBlock(x+8,y+ 26,z+ 20, a)
    mc.setBlock(x+8,y+ 25,z+ 20, a)
    mc.setBlock(x+37,y+ 24,z+ 20, a)
    mc.setBlock(x+36,y+ 24,z+ 20, a)
    mc.setBlock(x+35,y+ 24,z+ 20, a)
    mc.setBlock(x+38,y+ 23,z+ 20, a)
    mc.setBlock(x+48,y+ 9,z+ 41, a)
    mc.setBlock(x+49,y+ 9,z+ 41, a)
    mc.setBlock(x+50,y+ 9,z+ 41, a)
    mc.setBlock(x+34,y+ 23,z+ 20, a)
    mc.setBlock(x+33,y+ 23,z+ 20, a)
    mc.setBlock(x+8,y+ 23,z+ 20, a)
    mc.setBlock(x+7,y+ 23,z+ 20, a)
    mc.setBlock(x+6,y+ 23,z+ 20, a)
    mc.setBlock(x+5,y+ 23,z+ 20, a)
    mc.setBlock(x+38,y+ 22,z+ 20, a)
    mc.setBlock(x+51,y+ 9,z+ 41, a)
    mc.setBlock(x+48,y+ 10,z+ 41, a)
    mc.setBlock(x+32,y+ 22,z+ 20, a)
    mc.setBlock(x+8,y+ 22,z+ 20, a)
    mc.setBlock(x+49,y+ 10,z+ 41, a)
    mc.setBlock(x+50,y+ 10,z+ 41, a)
    mc.setBlock(x+48,y+ 11,z+ 41, a)
    mc.setBlock(x+4,y+ 22,z+ 20, a)
    mc.setBlock(x+38,y+ 21,z+ 20, a)
    mc.setBlock(x+32,y+ 21,z+ 20, a)
    mc.setBlock(x+9,y+ 21,z+ 20, a)
    mc.setBlock(x+31,y+ 18,z+ 41, a)
    mc.setBlock(x+30,y+ 19,z+ 41, a)
    mc.setBlock(x+4,y+ 21,z+ 20, a)
    mc.setBlock(x+38,y+ 20,z+ 20, a)
    mc.setBlock(x+31,y+ 19,z+ 41, a)
    mc.setBlock(x+32,y+ 19,z+ 41, a)
    mc.setBlock(x+31,y+ 20,z+ 20, a)
    mc.setBlock(x+9,y+ 20,z+ 20, a)
    mc.setBlock(x+4,y+ 20,z+ 20, a)
    mc.setBlock(x+37,y+ 19,z+ 20, a)
    mc.setBlock(x+29,y+ 20,z+ 41, a)
    mc.setBlock(x+31,y+ 19,z+ 20, a)
    mc.setBlock(x+9,y+ 19,z+ 20, a)
    mc.setBlock(x+4,y+ 19,z+ 20, a)
    mc.setBlock(x+37,y+ 18,z+ 20, a)
    mc.setBlock(x+30,y+ 20,z+ 41, a)
    mc.setBlock(x+31,y+ 20,z+ 41, a)
    mc.setBlock(x+32,y+ 20,z+ 41, a)
    mc.setBlock(x+31,y+ 18,z+ 20, a)
    mc.setBlock(x+9,y+ 18,z+ 20, a)
    mc.setBlock(x+33,y+ 20,z+ 41, a)
    mc.setBlock(x+4,y+ 18,z+ 20, a)
    mc.setBlock(x+36,y+ 17,z+ 20, a)
    mc.setBlock(x+35,y+ 17,z+ 20, a)
    mc.setBlock(x+34,y+ 17,z+ 20, a)
    mc.setBlock(x+33,y+ 17,z+ 20, a)
    mc.setBlock(x+32,y+ 17,z+ 20, a)
    mc.setBlock(x+9,y+ 17,z+ 20, a)
    mc.setBlock(x+36,y+ 20,z+ 41, a)
    mc.setBlock(x+37,y+ 20,z+ 41, a)
    mc.setBlock(x+27,y+ 21,z+ 41, a)
    mc.setBlock(x+5,y+ 17,z+ 20, a)
    mc.setBlock(x+8,y+ 16,z+ 20, a)
    mc.setBlock(x+7,y+ 16,z+ 20, a)
    mc.setBlock(x+6,y+ 16,z+ 20, a)
    mc.setBlock(x+21,y+ 63,z+ 19, a)
    mc.setBlock(x+20,y+ 63,z+ 19, a)
    mc.setBlock(x+21,y+ 62,z+ 19, a)
    mc.setBlock(x+20,y+ 62,z+ 19, a)
    mc.setBlock(x+36,y+ 52,z+ 19, a)
    mc.setBlock(x+35,y+ 52,z+ 19, a)
    mc.setBlock(x+34,y+ 52,z+ 19, a)
    mc.setBlock(x+33,y+ 52,z+ 19, a)
    mc.setBlock(x+37,y+ 51,z+ 19, a)
    mc.setBlock(x+28,y+ 21,z+ 41, a)
    mc.setBlock(x+29,y+ 21,z+ 41, a)
    mc.setBlock(x+30,y+ 21,z+ 41, a)
    mc.setBlock(x+31,y+ 21,z+ 41, a)
    mc.setBlock(x+32,y+ 51,z+ 19, a)
    mc.setBlock(x+38,y+ 50,z+ 19, a)
    mc.setBlock(x+32,y+ 21,z+ 41, a)
    mc.setBlock(x+33,y+ 21,z+ 41, a)
    mc.setBlock(x+32,y+ 50,z+ 19, a)
    mc.setBlock(x+39,y+ 49,z+ 19, a)
    mc.setBlock(x+34,y+ 21,z+ 41, a)
    mc.setBlock(x+35,y+ 21,z+ 41, a)
    mc.setBlock(x+32,y+ 49,z+ 19, a)
    mc.setBlock(x+39,y+ 48,z+ 19, a)
    mc.setBlock(x+36,y+ 21,z+ 41, a)
    mc.setBlock(x+32,y+ 48,z+ 19, a)
    mc.setBlock(x+39,y+ 47,z+ 19, a)
    mc.setBlock(x+37,y+ 21,z+ 41, a)
    mc.setBlock(x+25,y+ 22,z+ 41, a)
    mc.setBlock(x+33,y+ 47,z+ 19, a)
    mc.setBlock(x+39,y+ 46,z+ 19, a)
    mc.setBlock(x+26,y+ 22,z+ 41, a)
    mc.setBlock(x+27,y+ 22,z+ 41, a)
    mc.setBlock(x+33,y+ 22,z+ 41, a)
    mc.setBlock(x+34,y+ 22,z+ 41, a)
    mc.setBlock(x+34,y+ 46,z+ 19, a)
    mc.setBlock(x+39,y+ 45,z+ 19, a)
    mc.setBlock(x+38,y+ 45,z+ 19, a)
    mc.setBlock(x+37,y+ 45,z+ 19, a)
    mc.setBlock(x+36,y+ 45,z+ 19, a)
    mc.setBlock(x+35,y+ 45,z+ 19, a)
    mc.setBlock(x+50,y+ 31,z+ 19, a)
    mc.setBlock(x+49,y+ 31,z+ 19, a)
    mc.setBlock(x+48,y+ 31,z+ 19, a)
    mc.setBlock(x+47,y+ 31,z+ 19, a)
    mc.setBlock(x+46,y+ 31,z+ 19, a)
    mc.setBlock(x+28,y+ 31,z+ 19, a)
    mc.setBlock(x+27,y+ 31,z+ 19, a)
    mc.setBlock(x+26,y+ 31,z+ 19, a)
    mc.setBlock(x+51,y+ 30,z+ 19, a)
    mc.setBlock(x+35,y+ 22,z+ 41, a)
    mc.setBlock(x+36,y+ 22,z+ 41, a)
    mc.setBlock(x+46,y+ 30,z+ 19, a)
    mc.setBlock(x+28,y+ 30,z+ 19, a)
    mc.setBlock(x+23,y+ 23,z+ 41, a)
    mc.setBlock(x+26,y+ 30,z+ 19, a)
    mc.setBlock(x+51,y+ 29,z+ 19, a)
    mc.setBlock(x+24,y+ 23,z+ 41, a)
    mc.setBlock(x+34,y+ 23,z+ 41, a)
    mc.setBlock(x+46,y+ 29,z+ 19, a)
    mc.setBlock(x+28,y+ 29,z+ 19, a)
    mc.setBlock(x+27,y+ 29,z+ 19, a)
    mc.setBlock(x+51,y+ 28,z+ 19, a)
    mc.setBlock(x+35,y+ 23,z+ 41, a)
    mc.setBlock(x+16,y+ 24,z+ 41, a)
    mc.setBlock(x+17,y+ 24,z+ 41, a)
    mc.setBlock(x+47,y+ 28,z+ 19, a)
    mc.setBlock(x+46,y+ 28,z+ 19, a)
    mc.setBlock(x+50,y+ 27,z+ 19, a)
    mc.setBlock(x+49,y+ 27,z+ 19, a)
    mc.setBlock(x+48,y+ 27,z+ 19, a)
    mc.setBlock(x+37,y+ 23,z+ 19, a)
    mc.setBlock(x+36,y+ 23,z+ 19, a)
    mc.setBlock(x+35,y+ 23,z+ 19, a)
    mc.setBlock(x+34,y+ 23,z+ 19, a)
    mc.setBlock(x+37,y+ 22,z+ 19, a)
    mc.setBlock(x+18,y+ 24,z+ 41, a)
    mc.setBlock(x+19,y+ 24,z+ 41, a)
    mc.setBlock(x+20,y+ 24,z+ 41, a)
    mc.setBlock(x+33,y+ 22,z+ 19, a)
    mc.setBlock(x+32,y+ 22,z+ 19, a)
    mc.setBlock(x+8,y+ 22,z+ 19, a)
    mc.setBlock(x+7,y+ 22,z+ 19, a)
    mc.setBlock(x+6,y+ 22,z+ 19, a)
    mc.setBlock(x+5,y+ 22,z+ 19, a)
    mc.setBlock(x+38,y+ 21,z+ 19, a)
    mc.setBlock(x+21,y+ 24,z+ 41, a)
    mc.setBlock(x+22,y+ 24,z+ 41, a)
    mc.setBlock(x+31,y+ 21,z+ 19, a)
    mc.setBlock(x+9,y+ 21,z+ 19, a)
    mc.setBlock(x+33,y+ 24,z+ 41, a)
    mc.setBlock(x+35,y+ 24,z+ 41, a)
    mc.setBlock(x+5,y+ 21,z+ 19, a)
    mc.setBlock(x+37,y+ 20,z+ 19, a)
    mc.setBlock(x+31,y+ 20,z+ 19, a)
    mc.setBlock(x+10,y+ 20,z+ 19, a)
    mc.setBlock(x+15,y+ 25,z+ 41, a)
    mc.setBlock(x+33,y+ 25,z+ 41, a)
    mc.setBlock(x+4,y+ 20,z+ 19, a)
    mc.setBlock(x+37,y+ 19,z+ 19, a)
    mc.setBlock(x+34,y+ 25,z+ 41, a)
    mc.setBlock(x+14,y+ 26,z+ 41, a)
    mc.setBlock(x+30,y+ 19,z+ 19, a)
    mc.setBlock(x+10,y+ 19,z+ 19, a)
    mc.setBlock(x+31,y+ 26,z+ 41, a)
    mc.setBlock(x+4,y+ 19,z+ 19, a)
    mc.setBlock(x+37,y+ 18,z+ 19, a)
    mc.setBlock(x+32,y+ 26,z+ 41, a)
    mc.setBlock(x+14,y+ 27,z+ 41, a)
    mc.setBlock(x+30,y+ 18,z+ 19, a)
    mc.setBlock(x+10,y+ 18,z+ 19, a)
    mc.setBlock(x+28,y+ 27,z+ 41, a)
    mc.setBlock(x+29,y+ 27,z+ 41, a)
    mc.setBlock(x+4,y+ 18,z+ 19, a)
    mc.setBlock(x+36,y+ 17,z+ 19, a)
    mc.setBlock(x+30,y+ 27,z+ 41, a)
    mc.setBlock(x+14,y+ 28,z+ 41, a)
    mc.setBlock(x+26,y+ 28,z+ 41, a)
    mc.setBlock(x+31,y+ 17,z+ 19, a)
    mc.setBlock(x+30,y+ 17,z+ 19, a)
    mc.setBlock(x+10,y+ 17,z+ 19, a)
    mc.setBlock(x+27,y+ 28,z+ 41, a)
    mc.setBlock(x+15,y+ 29,z+ 41, a)
    mc.setBlock(x+16,y+ 29,z+ 41, a)
    mc.setBlock(x+5,y+ 17,z+ 19, a)
    mc.setBlock(x+35,y+ 16,z+ 19, a)
    mc.setBlock(x+34,y+ 16,z+ 19, a)
    mc.setBlock(x+33,y+ 16,z+ 19, a)
    mc.setBlock(x+32,y+ 16,z+ 19, a)
    mc.setBlock(x+31,y+ 16,z+ 19, a)
    mc.setBlock(x+9,y+ 16,z+ 19, a)
    mc.setBlock(x+8,y+ 16,z+ 19, a)
    mc.setBlock(x+7,y+ 16,z+ 19, a)
    mc.setBlock(x+6,y+ 16,z+ 19, a)
    mc.setBlock(x+21,y+ 63,z+ 18, a)
    mc.setBlock(x+20,y+ 63,z+ 18, a)
    mc.setBlock(x+22,y+ 62,z+ 18, a)
    mc.setBlock(x+17,y+ 29,z+ 41, a)
    mc.setBlock(x+20,y+ 62,z+ 18, a)
    mc.setBlock(x+23,y+ 61,z+ 18, a)
    mc.setBlock(x+22,y+ 61,z+ 18, a)
    mc.setBlock(x+21,y+ 61,z+ 18, a)
    mc.setBlock(x+24,y+ 60,z+ 18, a)
    mc.setBlock(x+23,y+ 60,z+ 18, a)
    mc.setBlock(x+22,y+ 60,z+ 18, a)
    mc.setBlock(x+24,y+ 59,z+ 18, a)
    mc.setBlock(x+23,y+ 59,z+ 18, a)
    mc.setBlock(x+35,y+ 53,z+ 18, a)
    mc.setBlock(x+34,y+ 53,z+ 18, a)
    mc.setBlock(x+36,y+ 52,z+ 18, a)
    mc.setBlock(x+18,y+ 29,z+ 41, a)
    mc.setBlock(x+19,y+ 29,z+ 41, a)
    mc.setBlock(x+33,y+ 52,z+ 18, a)
    mc.setBlock(x+32,y+ 52,z+ 18, a)
    mc.setBlock(x+37,y+ 51,z+ 18, a)
    mc.setBlock(x+20,y+ 29,z+ 41, a)
    mc.setBlock(x+21,y+ 29,z+ 41, a)
    mc.setBlock(x+32,y+ 51,z+ 18, a)
    mc.setBlock(x+38,y+ 50,z+ 18, a)
    mc.setBlock(x+22,y+ 29,z+ 41, a)
    mc.setBlock(x+23,y+ 29,z+ 41, a)
    mc.setBlock(x+31,y+ 50,z+ 18, a)
    mc.setBlock(x+38,y+ 49,z+ 18, a)
    mc.setBlock(x+24,y+ 29,z+ 41, a)
    mc.setBlock(x+31,y+ 49,z+ 18, a)
    mc.setBlock(x+39,y+ 48,z+ 18, a)
    mc.setBlock(x+25,y+ 29,z+ 41, a)
    mc.setBlock(x+54,y+ 4,z+ 42, a)
    mc.setBlock(x+32,y+ 48,z+ 18, a)
    mc.setBlock(x+39,y+ 47,z+ 18, a)
    mc.setBlock(x+55,y+ 4,z+ 42, a)
    mc.setBlock(x+52,y+ 5,z+ 42, a)
    mc.setBlock(x+53,y+ 5,z+ 42, a)
    mc.setBlock(x+33,y+ 47,z+ 18, a)
    mc.setBlock(x+38,y+ 46,z+ 18, a)
    mc.setBlock(x+37,y+ 46,z+ 18, a)
    mc.setBlock(x+36,y+ 46,z+ 18, a)
    mc.setBlock(x+35,y+ 46,z+ 18, a)
    mc.setBlock(x+34,y+ 46,z+ 18, a)
    mc.setBlock(x+25,y+ 44,z+ 18, a)
    mc.setBlock(x+25,y+ 43,z+ 18, a)
    mc.setBlock(x+24,y+ 43,z+ 18, a)
    mc.setBlock(x+25,y+ 42,z+ 18, a)
    mc.setBlock(x+24,y+ 42,z+ 18, a)
    mc.setBlock(x+50,y+ 32,z+ 18, a)
    mc.setBlock(x+49,y+ 32,z+ 18, a)
    mc.setBlock(x+48,y+ 32,z+ 18, a)
    mc.setBlock(x+50,y+ 31,z+ 18, a)
    mc.setBlock(x+54,y+ 5,z+ 42, a)
    mc.setBlock(x+48,y+ 6,z+ 42, a)
    mc.setBlock(x+47,y+ 31,z+ 18, a)
    mc.setBlock(x+46,y+ 31,z+ 18, a)
    mc.setBlock(x+51,y+ 30,z+ 18, a)
    mc.setBlock(x+49,y+ 6,z+ 42, a)
    mc.setBlock(x+50,y+ 6,z+ 42, a)
    mc.setBlock(x+51,y+ 6,z+ 42, a)
    mc.setBlock(x+53,y+ 6,z+ 42, a)
    mc.setBlock(x+54,y+ 6,z+ 42, a)
    mc.setBlock(x+45,y+ 30,z+ 18, a)
    mc.setBlock(x+27,y+ 30,z+ 18, a)
    mc.setBlock(x+26,y+ 30,z+ 18, a)
    mc.setBlock(x+51,y+ 29,z+ 18, a)
    mc.setBlock(x+55,y+ 6,z+ 42, a)
    mc.setBlock(x+49,y+ 29,z+ 18, a)
    mc.setBlock(x+48,y+ 29,z+ 18, a)
    mc.setBlock(x+56,y+ 6,z+ 42, a)
    mc.setBlock(x+46,y+ 29,z+ 18, a)
    mc.setBlock(x+45,y+ 29,z+ 18, a)
    mc.setBlock(x+51,y+ 28,z+ 18, a)
    mc.setBlock(x+50,y+ 28,z+ 18, a)
    mc.setBlock(x+49,y+ 28,z+ 18, a)
    mc.setBlock(x+48,y+ 28,z+ 18, a)
    mc.setBlock(x+47,y+ 28,z+ 18, a)
    mc.setBlock(x+36,y+ 22,z+ 18, a)
    mc.setBlock(x+35,y+ 22,z+ 18, a)
    mc.setBlock(x+34,y+ 22,z+ 18, a)
    mc.setBlock(x+33,y+ 22,z+ 18, a)
    mc.setBlock(x+32,y+ 22,z+ 18, a)
    mc.setBlock(x+8,y+ 22,z+ 18, a)
    mc.setBlock(x+7,y+ 22,z+ 18, a)
    mc.setBlock(x+6,y+ 22,z+ 18, a)
    mc.setBlock(x+37,y+ 21,z+ 18, a)
    mc.setBlock(x+47,y+ 7,z+ 42, a)
    mc.setBlock(x+48,y+ 7,z+ 42, a)
    mc.setBlock(x+49,y+ 7,z+ 42, a)
    mc.setBlock(x+53,y+ 7,z+ 42, a)
    mc.setBlock(x+31,y+ 21,z+ 18, a)
    mc.setBlock(x+9,y+ 21,z+ 18, a)
    mc.setBlock(x+54,y+ 7,z+ 42, a)
    mc.setBlock(x+55,y+ 7,z+ 42, a)
    mc.setBlock(x+56,y+ 7,z+ 42, a)
    mc.setBlock(x+5,y+ 21,z+ 18, a)
    mc.setBlock(x+37,y+ 20,z+ 18, a)
    mc.setBlock(x+57,y+ 7,z+ 42, a)
    mc.setBlock(x+58,y+ 7,z+ 42, a)
    mc.setBlock(x+30,y+ 20,z+ 18, a)
    mc.setBlock(x+10,y+ 20,z+ 18, a)
    mc.setBlock(x+47,y+ 8,z+ 42, a)
    mc.setBlock(x+5,y+ 20,z+ 18, a)
    mc.setBlock(x+37,y+ 19,z+ 18, a)
    mc.setBlock(x+48,y+ 8,z+ 42, a)
    mc.setBlock(x+53,y+ 8,z+ 42, a)
    mc.setBlock(x+30,y+ 19,z+ 18, a)
    mc.setBlock(x+10,y+ 19,z+ 18, a)
    mc.setBlock(x+54,y+ 8,z+ 42, a)
    mc.setBlock(x+4,y+ 19,z+ 18, a)
    mc.setBlock(x+36,y+ 18,z+ 18, a)
    mc.setBlock(x+30,y+ 18,z+ 18, a)
    mc.setBlock(x+11,y+ 18,z+ 18, a)
    mc.setBlock(x+55,y+ 8,z+ 42, a)
    mc.setBlock(x+5,y+ 18,z+ 18, a)
    mc.setBlock(x+36,y+ 17,z+ 18, a)
    mc.setBlock(x+56,y+ 8,z+ 42, a)
    mc.setBlock(x+57,y+ 8,z+ 42, a)
    mc.setBlock(x+30,y+ 17,z+ 18, a)
    mc.setBlock(x+11,y+ 17,z+ 18, a)
    mc.setBlock(x+58,y+ 8,z+ 42, a)
    mc.setBlock(x+59,y+ 8,z+ 42, a)
    mc.setBlock(x+5,y+ 17,z+ 18, a)
    mc.setBlock(x+35,y+ 16,z+ 18, a)
    mc.setBlock(x+34,y+ 16,z+ 18, a)
    mc.setBlock(x+46,y+ 9,z+ 42, a)
    mc.setBlock(x+47,y+ 9,z+ 42, a)
    mc.setBlock(x+51,y+ 9,z+ 42, a)
    mc.setBlock(x+30,y+ 16,z+ 18, a)
    mc.setBlock(x+10,y+ 16,z+ 18, a)
    mc.setBlock(x+9,y+ 16,z+ 18, a)
    mc.setBlock(x+52,y+ 9,z+ 42, a)
    mc.setBlock(x+7,y+ 16,z+ 18, a)
    mc.setBlock(x+6,y+ 16,z+ 18, a)
    mc.setBlock(x+33,y+ 15,z+ 18, a)
    mc.setBlock(x+32,y+ 15,z+ 18, a)
    mc.setBlock(x+31,y+ 15,z+ 18, a)
    mc.setBlock(x+8,y+ 15,z+ 18, a)
    mc.setBlock(x+21,y+ 63,z+ 17, a)
    mc.setBlock(x+20,y+ 63,z+ 17, a)
    mc.setBlock(x+22,y+ 62,z+ 17, a)
    mc.setBlock(x+21,y+ 62,z+ 17, a)
    mc.setBlock(x+20,y+ 62,z+ 17, a)
    mc.setBlock(x+23,y+ 61,z+ 17, a)
    mc.setBlock(x+53,y+ 9,z+ 42, a)
    mc.setBlock(x+21,y+ 61,z+ 17, a)
    mc.setBlock(x+24,y+ 60,z+ 17, a)
    mc.setBlock(x+54,y+ 9,z+ 42, a)
    mc.setBlock(x+22,y+ 60,z+ 17, a)
    mc.setBlock(x+25,y+ 59,z+ 17, a)
    mc.setBlock(x+55,y+ 9,z+ 42, a)
    mc.setBlock(x+23,y+ 59,z+ 17, a)
    mc.setBlock(x+25,y+ 58,z+ 17, a)
    mc.setBlock(x+24,y+ 58,z+ 17, a)
    mc.setBlock(x+36,y+ 53,z+ 17, a)
    mc.setBlock(x+35,y+ 53,z+ 17, a)
    mc.setBlock(x+34,y+ 53,z+ 17, a)
    mc.setBlock(x+33,y+ 53,z+ 17, a)
    mc.setBlock(x+32,y+ 53,z+ 17, a)
    mc.setBlock(x+36,y+ 52,z+ 17, a)
    mc.setBlock(x+56,y+ 9,z+ 42, a)
    mc.setBlock(x+57,y+ 9,z+ 42, a)
    mc.setBlock(x+58,y+ 9,z+ 42, a)
    mc.setBlock(x+31,y+ 52,z+ 17, a)
    mc.setBlock(x+37,y+ 51,z+ 17, a)
    mc.setBlock(x+46,y+ 10,z+ 42, a)
    mc.setBlock(x+31,y+ 51,z+ 17, a)
    mc.setBlock(x+38,y+ 50,z+ 17, a)
    mc.setBlock(x+47,y+ 10,z+ 42, a)
    mc.setBlock(x+31,y+ 50,z+ 17, a)
    mc.setBlock(x+38,y+ 49,z+ 17, a)
    mc.setBlock(x+50,y+ 10,z+ 42, a)
    mc.setBlock(x+54,y+ 10,z+ 42, a)
    mc.setBlock(x+31,y+ 49,z+ 17, a)
    mc.setBlock(x+38,y+ 48,z+ 17, a)
    mc.setBlock(x+55,y+ 10,z+ 42, a)
    mc.setBlock(x+45,y+ 11,z+ 42, a)
    mc.setBlock(x+31,y+ 48,z+ 17, a)
    mc.setBlock(x+38,y+ 47,z+ 17, a)
    mc.setBlock(x+37,y+ 47,z+ 17, a)
    mc.setBlock(x+46,y+ 11,z+ 42, a)
    mc.setBlock(x+47,y+ 11,z+ 42, a)
    mc.setBlock(x+49,y+ 11,z+ 42, a)
    mc.setBlock(x+33,y+ 47,z+ 17, a)
    mc.setBlock(x+32,y+ 47,z+ 17, a)
    mc.setBlock(x+37,y+ 46,z+ 17, a)
    mc.setBlock(x+36,y+ 46,z+ 17, a)
    mc.setBlock(x+35,y+ 46,z+ 17, a)
    mc.setBlock(x+34,y+ 46,z+ 17, a)
    mc.setBlock(x+27,y+ 45,z+ 17, a)
    mc.setBlock(x+26,y+ 45,z+ 17, a)
    mc.setBlock(x+26,y+ 44,z+ 17, a)
    mc.setBlock(x+25,y+ 44,z+ 17, a)
    mc.setBlock(x+26,y+ 43,z+ 17, a)
    mc.setBlock(x+44,y+ 12,z+ 42, a)
    mc.setBlock(x+24,y+ 43,z+ 17, a)
    mc.setBlock(x+25,y+ 42,z+ 17, a)
    mc.setBlock(x+24,y+ 42,z+ 17, a)
    mc.setBlock(x+50,y+ 32,z+ 17, a)
    mc.setBlock(x+49,y+ 32,z+ 17, a)
    mc.setBlock(x+48,y+ 32,z+ 17, a)
    mc.setBlock(x+50,y+ 31,z+ 17, a)
    mc.setBlock(x+45,y+ 12,z+ 42, a)
    mc.setBlock(x+46,y+ 12,z+ 42, a)
    mc.setBlock(x+47,y+ 31,z+ 17, a)
    mc.setBlock(x+46,y+ 31,z+ 17, a)
    mc.setBlock(x+45,y+ 31,z+ 17, a)
    mc.setBlock(x+50,y+ 30,z+ 17, a)
    mc.setBlock(x+49,y+ 30,z+ 17, a)
    mc.setBlock(x+48,y+ 30,z+ 17, a)
    mc.setBlock(x+47,y+ 12,z+ 42, a)
    mc.setBlock(x+48,y+ 12,z+ 42, a)
    mc.setBlock(x+45,y+ 30,z+ 17, a)
    mc.setBlock(x+52,y+ 29,z+ 17, a)
    mc.setBlock(x+51,y+ 29,z+ 17, a)
    mc.setBlock(x+50,y+ 29,z+ 17, a)
    mc.setBlock(x+47,y+ 29,z+ 17, a)
    mc.setBlock(x+46,y+ 29,z+ 17, a)
    mc.setBlock(x+45,y+ 29,z+ 17, a)
    mc.setBlock(x+52,y+ 28,z+ 17, a)
    mc.setBlock(x+51,y+ 28,z+ 17, a)
    mc.setBlock(x+50,y+ 28,z+ 17, a)
    mc.setBlock(x+35,y+ 22,z+ 17, a)
    mc.setBlock(x+34,y+ 22,z+ 17, a)
    mc.setBlock(x+33,y+ 22,z+ 17, a)
    mc.setBlock(x+36,y+ 21,z+ 17, a)
    mc.setBlock(x+49,y+ 12,z+ 42, a)
    mc.setBlock(x+43,y+ 13,z+ 42, a)
    mc.setBlock(x+44,y+ 13,z+ 42, a)
    mc.setBlock(x+32,y+ 21,z+ 17, a)
    mc.setBlock(x+31,y+ 21,z+ 17, a)
    mc.setBlock(x+9,y+ 21,z+ 17, a)
    mc.setBlock(x+8,y+ 21,z+ 17, a)
    mc.setBlock(x+7,y+ 21,z+ 17, a)
    mc.setBlock(x+6,y+ 21,z+ 17, a)
    mc.setBlock(x+36,y+ 20,z+ 17, a)
    mc.setBlock(x+45,y+ 13,z+ 42, a)
    mc.setBlock(x+46,y+ 13,z+ 42, a)
    mc.setBlock(x+30,y+ 20,z+ 17, a)
    mc.setBlock(x+10,y+ 20,z+ 17, a)
    mc.setBlock(x+47,y+ 13,z+ 42, a)
    mc.setBlock(x+42,y+ 14,z+ 42, a)
    mc.setBlock(x+5,y+ 20,z+ 17, a)
    mc.setBlock(x+36,y+ 19,z+ 17, a)
    mc.setBlock(x+43,y+ 14,z+ 42, a)
    mc.setBlock(x+44,y+ 14,z+ 42, a)
    mc.setBlock(x+29,y+ 19,z+ 17, a)
    mc.setBlock(x+26,y+ 19,z+ 17, a)
    mc.setBlock(x+25,y+ 19,z+ 17, a)
    mc.setBlock(x+11,y+ 19,z+ 17, a)
    mc.setBlock(x+45,y+ 14,z+ 42, a)
    mc.setBlock(x+5,y+ 19,z+ 17, a)
    mc.setBlock(x+36,y+ 18,z+ 17, a)
    mc.setBlock(x+46,y+ 14,z+ 42, a)
    mc.setBlock(x+41,y+ 15,z+ 42, a)
    mc.setBlock(x+29,y+ 18,z+ 17, a)
    mc.setBlock(x+26,y+ 18,z+ 17, a)
    mc.setBlock(x+25,y+ 18,z+ 17, a)
    mc.setBlock(x+24,y+ 18,z+ 17, a)
    mc.setBlock(x+11,y+ 18,z+ 17, a)
    mc.setBlock(x+5,y+ 18,z+ 17, a)
    mc.setBlock(x+36,y+ 17,z+ 17, a)
    mc.setBlock(x+42,y+ 15,z+ 42, a)
    mc.setBlock(x+29,y+ 17,z+ 17, a)
    mc.setBlock(x+11,y+ 17,z+ 17, a)
    mc.setBlock(x+43,y+ 15,z+ 42, a)
    mc.setBlock(x+44,y+ 15,z+ 42, a)
    mc.setBlock(x+5,y+ 17,z+ 17, a)
    mc.setBlock(x+35,y+ 16,z+ 17, a)
    mc.setBlock(x+45,y+ 15,z+ 42, a)
    mc.setBlock(x+40,y+ 16,z+ 42, a)
    mc.setBlock(x+41,y+ 16,z+ 42, a)
    mc.setBlock(x+29,y+ 16,z+ 17, a)
    mc.setBlock(x+11,y+ 16,z+ 17, a)
    mc.setBlock(x+42,y+ 16,z+ 42, a)
    mc.setBlock(x+43,y+ 16,z+ 42, a)
    mc.setBlock(x+44,y+ 16,z+ 42, a)
    mc.setBlock(x+38,y+ 17,z+ 42, a)
    mc.setBlock(x+6,y+ 16,z+ 17, a)
    mc.setBlock(x+34,y+ 15,z+ 17, a)
    mc.setBlock(x+33,y+ 15,z+ 17, a)
    mc.setBlock(x+32,y+ 15,z+ 17, a)
    mc.setBlock(x+31,y+ 15,z+ 17, a)
    mc.setBlock(x+30,y+ 15,z+ 17, a)
    mc.setBlock(x+29,y+ 15,z+ 17, a)
    mc.setBlock(x+10,y+ 15,z+ 17, a)
    mc.setBlock(x+9,y+ 15,z+ 17, a)
    mc.setBlock(x+8,y+ 15,z+ 17, a)
    mc.setBlock(x+7,y+ 15,z+ 17, a)
    mc.setBlock(x+23,y+ 61,z+ 16, a)
    mc.setBlock(x+22,y+ 61,z+ 16, a)
    mc.setBlock(x+24,y+ 60,z+ 16, a)
    mc.setBlock(x+39,y+ 17,z+ 42, a)
    mc.setBlock(x+22,y+ 60,z+ 16, a)
    mc.setBlock(x+25,y+ 59,z+ 16, a)
    mc.setBlock(x+40,y+ 17,z+ 42, a)
    mc.setBlock(x+23,y+ 59,z+ 16, a)
    mc.setBlock(x+26,y+ 58,z+ 16, a)
    mc.setBlock(x+41,y+ 17,z+ 42, a)
    mc.setBlock(x+24,y+ 58,z+ 16, a)
    mc.setBlock(x+26,y+ 57,z+ 16, a)
    mc.setBlock(x+25,y+ 57,z+ 16, a)
    mc.setBlock(x+36,y+ 53,z+ 16, a)
    mc.setBlock(x+35,y+ 53,z+ 16, a)
    mc.setBlock(x+34,y+ 53,z+ 16, a)
    mc.setBlock(x+33,y+ 53,z+ 16, a)
    mc.setBlock(x+32,y+ 53,z+ 16, a)
    mc.setBlock(x+31,y+ 53,z+ 16, a)
    mc.setBlock(x+37,y+ 52,z+ 16, a)
    mc.setBlock(x+42,y+ 17,z+ 42, a)
    mc.setBlock(x+43,y+ 17,z+ 42, a)
    mc.setBlock(x+31,y+ 52,z+ 16, a)
    mc.setBlock(x+37,y+ 51,z+ 16, a)
    mc.setBlock(x+44,y+ 17,z+ 42, a)
    mc.setBlock(x+30,y+ 51,z+ 16, a)
    mc.setBlock(x+37,y+ 50,z+ 16, a)
    mc.setBlock(x+37,y+ 18,z+ 42, a)
    mc.setBlock(x+30,y+ 50,z+ 16, a)
    mc.setBlock(x+37,y+ 49,z+ 16, a)
    mc.setBlock(x+38,y+ 18,z+ 42, a)
    mc.setBlock(x+30,y+ 49,z+ 16, a)
    mc.setBlock(x+37,y+ 48,z+ 16, a)
    mc.setBlock(x+39,y+ 18,z+ 42, a)
    mc.setBlock(x+40,y+ 18,z+ 42, a)
    mc.setBlock(x+31,y+ 48,z+ 16, a)
    mc.setBlock(x+36,y+ 47,z+ 16, a)
    mc.setBlock(x+35,y+ 47,z+ 16, a)
    mc.setBlock(x+34,y+ 47,z+ 16, a)
    mc.setBlock(x+33,y+ 47,z+ 16, a)
    mc.setBlock(x+32,y+ 47,z+ 16, a)
    mc.setBlock(x+28,y+ 46,z+ 16, a)
    mc.setBlock(x+27,y+ 46,z+ 16, a)
    mc.setBlock(x+27,y+ 45,z+ 16, a)
    mc.setBlock(x+26,y+ 45,z+ 16, a)
    mc.setBlock(x+27,y+ 44,z+ 16, a)
    mc.setBlock(x+41,y+ 18,z+ 42, a)
    mc.setBlock(x+25,y+ 44,z+ 16, a)
    mc.setBlock(x+26,y+ 43,z+ 16, a)
    mc.setBlock(x+25,y+ 43,z+ 16, a)
    mc.setBlock(x+50,y+ 32,z+ 16, a)
    mc.setBlock(x+49,y+ 32,z+ 16, a)
    mc.setBlock(x+48,y+ 32,z+ 16, a)
    mc.setBlock(x+50,y+ 31,z+ 16, a)
    mc.setBlock(x+49,y+ 31,z+ 16, a)
    mc.setBlock(x+48,y+ 31,z+ 16, a)
    mc.setBlock(x+47,y+ 31,z+ 16, a)
    mc.setBlock(x+46,y+ 31,z+ 16, a)
    mc.setBlock(x+47,y+ 30,z+ 16, a)
    mc.setBlock(x+42,y+ 18,z+ 42, a)
    mc.setBlock(x+45,y+ 30,z+ 16, a)
    mc.setBlock(x+51,y+ 29,z+ 16, a)
    mc.setBlock(x+50,y+ 29,z+ 16, a)
    mc.setBlock(x+47,y+ 29,z+ 16, a)
    mc.setBlock(x+46,y+ 29,z+ 16, a)
    mc.setBlock(x+45,y+ 29,z+ 16, a)
    mc.setBlock(x+51,y+ 28,z+ 16, a)
    mc.setBlock(x+50,y+ 28,z+ 16, a)
    mc.setBlock(x+35,y+ 21,z+ 16, a)
    mc.setBlock(x+34,y+ 21,z+ 16, a)
    mc.setBlock(x+33,y+ 21,z+ 16, a)
    mc.setBlock(x+32,y+ 21,z+ 16, a)
    mc.setBlock(x+9,y+ 21,z+ 16, a)
    mc.setBlock(x+8,y+ 21,z+ 16, a)
    mc.setBlock(x+7,y+ 21,z+ 16, a)
    mc.setBlock(x+35,y+ 20,z+ 16, a)
    mc.setBlock(x+43,y+ 18,z+ 42, a)
    mc.setBlock(x+32,y+ 19,z+ 42, a)
    mc.setBlock(x+35,y+ 19,z+ 42, a)
    mc.setBlock(x+31,y+ 20,z+ 16, a)
    mc.setBlock(x+30,y+ 20,z+ 16, a)
    mc.setBlock(x+11,y+ 20,z+ 16, a)
    mc.setBlock(x+10,y+ 20,z+ 16, a)
    mc.setBlock(x+36,y+ 19,z+ 42, a)
    mc.setBlock(x+37,y+ 19,z+ 42, a)
    mc.setBlock(x+38,y+ 19,z+ 42, a)
    mc.setBlock(x+6,y+ 20,z+ 16, a)
    mc.setBlock(x+35,y+ 19,z+ 16, a)
    mc.setBlock(x+39,y+ 19,z+ 42, a)
    mc.setBlock(x+40,y+ 19,z+ 42, a)
    mc.setBlock(x+29,y+ 19,z+ 16, a)
    mc.setBlock(x+12,y+ 19,z+ 16, a)
    mc.setBlock(x+41,y+ 19,z+ 42, a)
    mc.setBlock(x+42,y+ 19,z+ 42, a)
    mc.setBlock(x+5,y+ 19,z+ 16, a)
    mc.setBlock(x+35,y+ 18,z+ 16, a)
    mc.setBlock(x+31,y+ 20,z+ 42, a)
    mc.setBlock(x+28,y+ 18,z+ 16, a)
    mc.setBlock(x+27,y+ 18,z+ 16, a)
    mc.setBlock(x+26,y+ 18,z+ 16, a)
    mc.setBlock(x+25,y+ 18,z+ 16, a)
    mc.setBlock(x+24,y+ 18,z+ 16, a)
    mc.setBlock(x+23,y+ 18,z+ 16, a)
    mc.setBlock(x+22,y+ 18,z+ 16, a)
    mc.setBlock(x+21,y+ 18,z+ 16, a)
    mc.setBlock(x+12,y+ 18,z+ 16, a)
    mc.setBlock(x+33,y+ 20,z+ 42, a)
    mc.setBlock(x+34,y+ 20,z+ 42, a)
    mc.setBlock(x+5,y+ 18,z+ 16, a)
    mc.setBlock(x+35,y+ 17,z+ 16, a)
    mc.setBlock(x+35,y+ 20,z+ 42, a)
    mc.setBlock(x+38,y+ 20,z+ 42, a)
    mc.setBlock(x+28,y+ 17,z+ 16, a)
    mc.setBlock(x+27,y+ 17,z+ 16, a)
    mc.setBlock(x+12,y+ 17,z+ 16, a)
    mc.setBlock(x+39,y+ 20,z+ 42, a)
    mc.setBlock(x+6,y+ 17,z+ 16, a)
    mc.setBlock(x+35,y+ 16,z+ 16, a)
    mc.setBlock(x+40,y+ 20,z+ 42, a)
    mc.setBlock(x+41,y+ 20,z+ 42, a)
    mc.setBlock(x+28,y+ 16,z+ 16, a)
    mc.setBlock(x+27,y+ 16,z+ 16, a)
    mc.setBlock(x+12,y+ 16,z+ 16, a)
    mc.setBlock(x+27,y+ 21,z+ 42, a)
    mc.setBlock(x+28,y+ 21,z+ 42, a)
    mc.setBlock(x+6,y+ 16,z+ 16, a)
    mc.setBlock(x+34,y+ 15,z+ 16, a)
    mc.setBlock(x+33,y+ 15,z+ 16, a)
    mc.setBlock(x+29,y+ 21,z+ 42, a)
    mc.setBlock(x+30,y+ 21,z+ 42, a)
    mc.setBlock(x+38,y+ 21,z+ 42, a)
    mc.setBlock(x+39,y+ 21,z+ 42, a)
    mc.setBlock(x+28,y+ 15,z+ 16, a)
    mc.setBlock(x+27,y+ 15,z+ 16, a)
    mc.setBlock(x+12,y+ 15,z+ 16, a)
    mc.setBlock(x+11,y+ 15,z+ 16, a)
    mc.setBlock(x+10,y+ 15,z+ 16, a)
    mc.setBlock(x+9,y+ 15,z+ 16, a)
    mc.setBlock(x+8,y+ 15,z+ 16, a)
    mc.setBlock(x+7,y+ 15,z+ 16, a)
    mc.setBlock(x+32,y+ 14,z+ 16, a)
    mc.setBlock(x+31,y+ 14,z+ 16, a)
    mc.setBlock(x+30,y+ 14,z+ 16, a)
    mc.setBlock(x+29,y+ 14,z+ 16, a)
    mc.setBlock(x+28,y+ 14,z+ 16, a)
    mc.setBlock(x+27,y+ 14,z+ 16, a)
    mc.setBlock(x+49,y+ 62,z+ 15, a)
    mc.setBlock(x+48,y+ 62,z+ 15, a)
    mc.setBlock(x+48,y+ 61,z+ 15, a)
    mc.setBlock(x+47,y+ 61,z+ 15, a)
    mc.setBlock(x+47,y+ 60,z+ 15, a)
    mc.setBlock(x+46,y+ 60,z+ 15, a)
    mc.setBlock(x+24,y+ 60,z+ 15, a)
    mc.setBlock(x+23,y+ 60,z+ 15, a)
    mc.setBlock(x+46,y+ 59,z+ 15, a)
    mc.setBlock(x+45,y+ 59,z+ 15, a)
    mc.setBlock(x+25,y+ 59,z+ 15, a)
    mc.setBlock(x+24,y+ 59,z+ 15, a)
    mc.setBlock(x+23,y+ 59,z+ 15, a)
    mc.setBlock(x+45,y+ 58,z+ 15, a)
    mc.setBlock(x+44,y+ 58,z+ 15, a)
    mc.setBlock(x+26,y+ 58,z+ 15, a)
    mc.setBlock(x+40,y+ 21,z+ 42, a)
    mc.setBlock(x+24,y+ 58,z+ 15, a)
    mc.setBlock(x+27,y+ 57,z+ 15, a)
    mc.setBlock(x+24,y+ 22,z+ 42, a)
    mc.setBlock(x+25,y+ 57,z+ 15, a)
    mc.setBlock(x+28,y+ 56,z+ 15, a)
    mc.setBlock(x+27,y+ 56,z+ 15, a)
    mc.setBlock(x+26,y+ 56,z+ 15, a)
    mc.setBlock(x+28,y+ 55,z+ 15, a)
    mc.setBlock(x+27,y+ 55,z+ 15, a)
    mc.setBlock(x+35,y+ 54,z+ 15, a)
    mc.setBlock(x+34,y+ 54,z+ 15, a)
    mc.setBlock(x+33,y+ 54,z+ 15, a)
    mc.setBlock(x+32,y+ 54,z+ 15, a)
    mc.setBlock(x+36,y+ 53,z+ 15, a)
    mc.setBlock(x+25,y+ 22,z+ 42, a)
    mc.setBlock(x+26,y+ 22,z+ 42, a)
    mc.setBlock(x+37,y+ 22,z+ 42, a)
    mc.setBlock(x+38,y+ 22,z+ 42, a)
    mc.setBlock(x+31,y+ 53,z+ 15, a)
    mc.setBlock(x+37,y+ 52,z+ 15, a)
    mc.setBlock(x+39,y+ 22,z+ 42, a)
    mc.setBlock(x+23,y+ 23,z+ 42, a)
    mc.setBlock(x+30,y+ 52,z+ 15, a)
    mc.setBlock(x+37,y+ 51,z+ 15, a)
    mc.setBlock(x+36,y+ 23,z+ 42, a)
    mc.setBlock(x+30,y+ 51,z+ 15, a)
    mc.setBlock(x+37,y+ 50,z+ 15, a)
    mc.setBlock(x+30,y+ 50,z+ 15, a)
    mc.setBlock(x+37,y+ 49,z+ 15, a)
    mc.setBlock(x+37,y+ 23,z+ 42, a)
    mc.setBlock(x+18,y+ 24,z+ 42, a)
    mc.setBlock(x+30,y+ 49,z+ 15, a)
    mc.setBlock(x+36,y+ 48,z+ 15, a)
    mc.setBlock(x+19,y+ 24,z+ 42, a)
    mc.setBlock(x+20,y+ 24,z+ 42, a)
    mc.setBlock(x+21,y+ 24,z+ 42, a)
    mc.setBlock(x+30,y+ 48,z+ 15, a)
    mc.setBlock(x+29,y+ 48,z+ 15, a)
    mc.setBlock(x+35,y+ 47,z+ 15, a)
    mc.setBlock(x+34,y+ 47,z+ 15, a)
    mc.setBlock(x+33,y+ 47,z+ 15, a)
    mc.setBlock(x+32,y+ 47,z+ 15, a)
    mc.setBlock(x+31,y+ 47,z+ 15, a)
    mc.setBlock(x+29,y+ 47,z+ 15, a)
    mc.setBlock(x+28,y+ 47,z+ 15, a)
    mc.setBlock(x+28,y+ 46,z+ 15, a)
    mc.setBlock(x+27,y+ 46,z+ 15, a)
    mc.setBlock(x+41,y+ 45,z+ 15, a)
    mc.setBlock(x+28,y+ 45,z+ 15, a)
    mc.setBlock(x+22,y+ 24,z+ 42, a)
    mc.setBlock(x+26,y+ 45,z+ 15, a)
    mc.setBlock(x+42,y+ 44,z+ 15, a)
    mc.setBlock(x+41,y+ 44,z+ 15, a)
    mc.setBlock(x+27,y+ 44,z+ 15, a)
    mc.setBlock(x+26,y+ 44,z+ 15, a)
    mc.setBlock(x+42,y+ 43,z+ 15, a)
    mc.setBlock(x+41,y+ 43,z+ 15, a)
    mc.setBlock(x+43,y+ 42,z+ 15, a)
    mc.setBlock(x+42,y+ 42,z+ 15, a)
    mc.setBlock(x+50,y+ 32,z+ 15, a)
    mc.setBlock(x+49,y+ 32,z+ 15, a)
    mc.setBlock(x+50,y+ 31,z+ 15, a)
    mc.setBlock(x+49,y+ 31,z+ 15, a)
    mc.setBlock(x+47,y+ 30,z+ 15, a)
    mc.setBlock(x+46,y+ 30,z+ 15, a)
    mc.setBlock(x+51,y+ 29,z+ 15, a)
    mc.setBlock(x+50,y+ 29,z+ 15, a)
    mc.setBlock(x+46,y+ 29,z+ 15, a)
    mc.setBlock(x+51,y+ 28,z+ 15, a)
    mc.setBlock(x+50,y+ 28,z+ 15, a)
    mc.setBlock(x+34,y+ 20,z+ 15, a)
    mc.setBlock(x+33,y+ 20,z+ 15, a)
    mc.setBlock(x+32,y+ 20,z+ 15, a)
    mc.setBlock(x+31,y+ 20,z+ 15, a)
    mc.setBlock(x+30,y+ 20,z+ 15, a)
    mc.setBlock(x+11,y+ 20,z+ 15, a)
    mc.setBlock(x+10,y+ 20,z+ 15, a)
    mc.setBlock(x+9,y+ 20,z+ 15, a)
    mc.setBlock(x+8,y+ 20,z+ 15, a)
    mc.setBlock(x+7,y+ 20,z+ 15, a)
    mc.setBlock(x+6,y+ 20,z+ 15, a)
    mc.setBlock(x+35,y+ 19,z+ 15, a)
    mc.setBlock(x+36,y+ 24,z+ 42, a)
    mc.setBlock(x+16,y+ 25,z+ 42, a)
    mc.setBlock(x+17,y+ 25,z+ 42, a)
    mc.setBlock(x+29,y+ 19,z+ 15, a)
    mc.setBlock(x+12,y+ 19,z+ 15, a)
    mc.setBlock(x+34,y+ 25,z+ 42, a)
    mc.setBlock(x+35,y+ 25,z+ 42, a)
    mc.setBlock(x+6,y+ 19,z+ 15, a)
    mc.setBlock(x+35,y+ 18,z+ 15, a)
    mc.setBlock(x+15,y+ 26,z+ 42, a)
    mc.setBlock(x+16,y+ 26,z+ 42, a)
    mc.setBlock(x+28,y+ 18,z+ 15, a)
    mc.setBlock(x+27,y+ 18,z+ 15, a)
    mc.setBlock(x+26,y+ 18,z+ 15, a)
    mc.setBlock(x+25,y+ 18,z+ 15, a)
    mc.setBlock(x+24,y+ 18,z+ 15, a)
    mc.setBlock(x+23,y+ 18,z+ 15, a)
    mc.setBlock(x+22,y+ 18,z+ 15, a)
    mc.setBlock(x+21,y+ 18,z+ 15, a)
    mc.setBlock(x+20,y+ 18,z+ 15, a)
    mc.setBlock(x+19,y+ 18,z+ 15, a)
    mc.setBlock(x+13,y+ 18,z+ 15, a)
    mc.setBlock(x+32,y+ 26,z+ 42, a)
    mc.setBlock(x+33,y+ 26,z+ 42, a)
    mc.setBlock(x+6,y+ 18,z+ 15, a)
    mc.setBlock(x+35,y+ 17,z+ 15, a)
    mc.setBlock(x+15,y+ 27,z+ 42, a)
    mc.setBlock(x+16,y+ 27,z+ 42, a)
    mc.setBlock(x+29,y+ 27,z+ 42, a)
    mc.setBlock(x+26,y+ 17,z+ 15, a)
    mc.setBlock(x+25,y+ 17,z+ 15, a)
    mc.setBlock(x+24,y+ 17,z+ 15, a)
    mc.setBlock(x+23,y+ 17,z+ 15, a)
    mc.setBlock(x+22,y+ 17,z+ 15, a)
    mc.setBlock(x+21,y+ 17,z+ 15, a)
    mc.setBlock(x+20,y+ 17,z+ 15, a)
    mc.setBlock(x+19,y+ 17,z+ 15, a)
    mc.setBlock(x+13,y+ 17,z+ 15, a)
    mc.setBlock(x+30,y+ 27,z+ 42, a)
    mc.setBlock(x+31,y+ 27,z+ 42, a)
    mc.setBlock(x+6,y+ 17,z+ 15, a)
    mc.setBlock(x+34,y+ 16,z+ 15, a)
    mc.setBlock(x+15,y+ 28,z+ 42, a)
    mc.setBlock(x+16,y+ 28,z+ 42, a)
    mc.setBlock(x+26,y+ 16,z+ 15, a)
    mc.setBlock(x+13,y+ 16,z+ 15, a)
    mc.setBlock(x+26,y+ 28,z+ 42, a)
    mc.setBlock(x+27,y+ 28,z+ 42, a)
    mc.setBlock(x+6,y+ 16,z+ 15, a)
    mc.setBlock(x+33,y+ 15,z+ 15, a)
    mc.setBlock(x+28,y+ 28,z+ 42, a)
    mc.setBlock(x+17,y+ 29,z+ 42, a)
    mc.setBlock(x+26,y+ 15,z+ 15, a)
    mc.setBlock(x+13,y+ 15,z+ 15, a)
    mc.setBlock(x+18,y+ 29,z+ 42, a)
    mc.setBlock(x+19,y+ 29,z+ 42, a)
    mc.setBlock(x+20,y+ 29,z+ 42, a)
    mc.setBlock(x+21,y+ 29,z+ 42, a)
    mc.setBlock(x+8,y+ 15,z+ 15, a)
    mc.setBlock(x+7,y+ 15,z+ 15, a)
    mc.setBlock(x+32,y+ 14,z+ 15, a)
    mc.setBlock(x+31,y+ 14,z+ 15, a)
    mc.setBlock(x+22,y+ 29,z+ 42, a)
    mc.setBlock(x+23,y+ 29,z+ 42, a)
    mc.setBlock(x+24,y+ 29,z+ 42, a)
    mc.setBlock(x+25,y+ 29,z+ 42, a)
    mc.setBlock(x+26,y+ 14,z+ 15, a)
    mc.setBlock(x+12,y+ 14,z+ 15, a)
    mc.setBlock(x+11,y+ 14,z+ 15, a)
    mc.setBlock(x+10,y+ 14,z+ 15, a)
    mc.setBlock(x+9,y+ 14,z+ 15, a)
    mc.setBlock(x+30,y+ 13,z+ 15, a)
    mc.setBlock(x+29,y+ 13,z+ 15, a)
    mc.setBlock(x+28,y+ 13,z+ 15, a)
    mc.setBlock(x+27,y+ 13,z+ 15, a)
    mc.setBlock(x+28,y+ 12,z+ 15, a)
    mc.setBlock(x+28,y+ 11,z+ 15, a)
    mc.setBlock(x+27,y+ 11,z+ 15, a)
    mc.setBlock(x+28,y+ 10,z+ 15, a)
    mc.setBlock(x+27,y+ 10,z+ 15, a)
    mc.setBlock(x+27,y+ 9,z+ 15, a)
    mc.setBlock(x+26,y+ 9,z+ 15, a)
    mc.setBlock(x+49,y+ 63,z+ 14, a)
    mc.setBlock(x+49,y+ 62,z+ 14, a)
    mc.setBlock(x+48,y+ 62,z+ 14, a)
    mc.setBlock(x+48,y+ 61,z+ 14, a)
    mc.setBlock(x+47,y+ 61,z+ 14, a)
    mc.setBlock(x+46,y+ 61,z+ 14, a)
    mc.setBlock(x+47,y+ 60,z+ 14, a)
    mc.setBlock(x+52,y+ 6,z+ 43, a)
    mc.setBlock(x+45,y+ 60,z+ 14, a)
    mc.setBlock(x+46,y+ 59,z+ 14, a)
    mc.setBlock(x+50,y+ 7,z+ 43, a)
    mc.setBlock(x+44,y+ 59,z+ 14, a)
    mc.setBlock(x+45,y+ 58,z+ 14, a)
    mc.setBlock(x+44,y+ 58,z+ 14, a)
    mc.setBlock(x+43,y+ 58,z+ 14, a)
    mc.setBlock(x+26,y+ 58,z+ 14, a)
    mc.setBlock(x+25,y+ 58,z+ 14, a)
    mc.setBlock(x+43,y+ 57,z+ 14, a)
    mc.setBlock(x+42,y+ 57,z+ 14, a)
    mc.setBlock(x+27,y+ 57,z+ 14, a)
    mc.setBlock(x+51,y+ 7,z+ 43, a)
    mc.setBlock(x+25,y+ 57,z+ 14, a)
    mc.setBlock(x+42,y+ 56,z+ 14, a)
    mc.setBlock(x+28,y+ 56,z+ 14, a)
    mc.setBlock(x+52,y+ 7,z+ 43, a)
    mc.setBlock(x+26,y+ 56,z+ 14, a)
    mc.setBlock(x+29,y+ 55,z+ 14, a)
    mc.setBlock(x+48,y+ 8,z+ 43, a)
    mc.setBlock(x+27,y+ 55,z+ 14, a)
    mc.setBlock(x+35,y+ 54,z+ 14, a)
    mc.setBlock(x+34,y+ 54,z+ 14, a)
    mc.setBlock(x+33,y+ 54,z+ 14, a)
    mc.setBlock(x+32,y+ 54,z+ 14, a)
    mc.setBlock(x+31,y+ 54,z+ 14, a)
    mc.setBlock(x+30,y+ 54,z+ 14, a)
    mc.setBlock(x+29,y+ 54,z+ 14, a)
    mc.setBlock(x+28,y+ 54,z+ 14, a)
    mc.setBlock(x+37,y+ 53,z+ 14, a)
    mc.setBlock(x+36,y+ 53,z+ 14, a)
    mc.setBlock(x+49,y+ 8,z+ 43, a)
    mc.setBlock(x+50,y+ 8,z+ 43, a)
    mc.setBlock(x+51,y+ 8,z+ 43, a)
    mc.setBlock(x+30,y+ 53,z+ 14, a)
    mc.setBlock(x+29,y+ 53,z+ 14, a)
    mc.setBlock(x+37,y+ 52,z+ 14, a)
    mc.setBlock(x+30,y+ 52,z+ 14, a)
    mc.setBlock(x+37,y+ 51,z+ 14, a)
    mc.setBlock(x+30,y+ 51,z+ 14, a)
    mc.setBlock(x+37,y+ 50,z+ 14, a)
    mc.setBlock(x+30,y+ 50,z+ 14, a)
    mc.setBlock(x+37,y+ 49,z+ 14, a)
    mc.setBlock(x+52,y+ 8,z+ 43, a)
    mc.setBlock(x+29,y+ 49,z+ 14, a)
    mc.setBlock(x+37,y+ 48,z+ 14, a)
    mc.setBlock(x+47,y+ 9,z+ 43, a)
    mc.setBlock(x+50,y+ 9,z+ 43, a)
    mc.setBlock(x+51,y+ 9,z+ 43, a)
    mc.setBlock(x+30,y+ 48,z+ 14, a)
    mc.setBlock(x+52,y+ 9,z+ 43, a)
    mc.setBlock(x+28,y+ 48,z+ 14, a)
    mc.setBlock(x+39,y+ 47,z+ 14, a)
    mc.setBlock(x+38,y+ 47,z+ 14, a)
    mc.setBlock(x+36,y+ 47,z+ 14, a)
    mc.setBlock(x+35,y+ 47,z+ 14, a)
    mc.setBlock(x+34,y+ 47,z+ 14, a)
    mc.setBlock(x+33,y+ 47,z+ 14, a)
    mc.setBlock(x+32,y+ 47,z+ 14, a)
    mc.setBlock(x+31,y+ 47,z+ 14, a)
    mc.setBlock(x+29,y+ 47,z+ 14, a)
    mc.setBlock(x+28,y+ 47,z+ 14, a)
    mc.setBlock(x+40,y+ 46,z+ 14, a)
    mc.setBlock(x+39,y+ 46,z+ 14, a)
    mc.setBlock(x+38,y+ 46,z+ 14, a)
    mc.setBlock(x+28,y+ 46,z+ 14, a)
    mc.setBlock(x+27,y+ 46,z+ 14, a)
    mc.setBlock(x+41,y+ 45,z+ 14, a)
    mc.setBlock(x+40,y+ 45,z+ 14, a)
    mc.setBlock(x+39,y+ 45,z+ 14, a)
    mc.setBlock(x+28,y+ 45,z+ 14, a)
    mc.setBlock(x+27,y+ 45,z+ 14, a)
    mc.setBlock(x+42,y+ 44,z+ 14, a)
    mc.setBlock(x+53,y+ 9,z+ 43, a)
    mc.setBlock(x+40,y+ 44,z+ 14, a)
    mc.setBlock(x+42,y+ 43,z+ 14, a)
    mc.setBlock(x+41,y+ 43,z+ 14, a)
    mc.setBlock(x+43,y+ 42,z+ 14, a)
    mc.setBlock(x+42,y+ 42,z+ 14, a)
    mc.setBlock(x+32,y+ 20,z+ 14, a)
    mc.setBlock(x+31,y+ 20,z+ 14, a)
    mc.setBlock(x+11,y+ 20,z+ 14, a)
    mc.setBlock(x+10,y+ 20,z+ 14, a)
    mc.setBlock(x+9,y+ 20,z+ 14, a)
    mc.setBlock(x+8,y+ 20,z+ 14, a)
    mc.setBlock(x+34,y+ 19,z+ 14, a)
    mc.setBlock(x+33,y+ 19,z+ 14, a)
    mc.setBlock(x+54,y+ 9,z+ 43, a)
    mc.setBlock(x+55,y+ 9,z+ 43, a)
    mc.setBlock(x+30,y+ 19,z+ 14, a)
    mc.setBlock(x+29,y+ 19,z+ 14, a)
    mc.setBlock(x+28,y+ 19,z+ 14, a)
